Workbook

Sheet Camargo
A1: ENCUESTA DE LARVARIA DE AEDES AEGYPTI POR COMUNIDAD - BARRIOS DE CAMARGO GESTION 2025
A2: ç
A3: Establecimiento | B3: Barrio / Comunidad | C3: Habitantaes protegidos | D3: FECHA | F3: PREDIOS | K3: TOTAL PREDIOS | L3: Manzanos | N3: VIVIENDAS | P3: Grupo A Depositos de Almacenamiento de Gran Volumen | V3: Grupo B Depositos de Transporte de Agua Moviles | Y3: Grupo C Depositos Fijos de Almacenamiento de Agua | AB3: Grupo D Depositos para Eliminacion | AH3: Grupo E Depositos Naturales | AK3: TOTAL | AO3: indicadores | AT3: INDICADORES DE ENTOMOLOGICOS - TIPO RECIPIENTE
D4: Inicio | E4: Final | F4: INSPECCIONADAS | H4: TOTAL | I4: Cerradas | J4: Renuentes | L4: EVALUADAS | M4: FOCO AEDES | N4: CON FOCO | O4: FOCO AEDES | P4: A1 | S4: A2 | V4: B | Y4: C | AB4: D1 | AE4: D2 | AH4: E | AK4: Total Recipinetes Secos | AL4: Total Recipinetes Agua | AM4: Total Recipinetes | AN4: Total Recipinetes Positivos (+) | AO4: Entomologico | AR4: Recipiente | AT4: Indice por tipo de recipiente A1 | AU4: Indice por tipo de recipiente A2 | AV4: Indice por tipo de recipiente B | AW4: Indice por tipo de recipiente C | AX4: Indice por tipo de recipiente D1 | AY4: Indice por tipo de recipiente D2 | AZ4: Indice por tipo de recipiente E
F5: Vivienda | G5: T . Baldio | P5: S | Q5: A | R5: POSITIVOS (+) | S5: S | T5: A | U5: POSITIVOS (+) | V5: S | W5: A | X5: POSITIVOS (+) | Y5: S | Z5: A | AA5: POSITIVOS (+) | AB5: S | AC5: A | AD5: POSITIVOS (+) | AE5: S | AF5: A | AG5: POSITIVOS (+) | AH5: S | AI5: A | AJ5: POSITIVOS (+) | AO5: % Indice de Infestacion | AP5: % Indice Bretau | AQ5: % Indice Recipiente | AR5: % Recipientes secos | AS5: % Recipientes con agua
A6: Hosp. San Juan de Dios Camargo | B6: Barrio El Recreo | C6: 381 | D6: 45757 | E6: 45776 | F6: 86 | G6: 0 | H6: =F6+G6 -> 86 | I6: 0 | J6: 0 | K6: =H6+I6+J6 -> 86 | L6: 0 | M6: 0 | N6: 86 | O6: 0 | P6: 0 | Q6: 54 | R6: 0 | S6: 31 | T6: 38 | U6: 0 | V6: 0 | W6: 0 | X6: 0 | Y6: 9 | Z6: 108 | AA6: 0 | AB6: 68 | AC6: 41 | AD6: 0 | AE6: 1334 | AF6: 271 | AG6: 0 | AH6: 0 | AI6: 0 | AJ6: 0 | AK6: =P6+S6+V6+Y6+AB6+AE6+AH6 -> 1442 | AL6: =Q6+T6+W6+Z6+AC6+AF6+AI6 -> 512 | AM6: =AK6+AL6 -> 1954 | AN6: =R6+U6+X6+AA6+AD6+AG6+AJ6 -> 0 | AO6: =O6/H6*100 -> 0 | AP6: =AN6/H6*100 -> 0 | AQ6: =AN6/AM6*100 -> 0 | AR6: =AK6/AM6*100 -> 73.797339 | AS6: =AL6/AM6*100 -> 26.202661 | AT6: =R6/AN6*100 -> #DIV/0! | AU6: =U6/AN6*100 -> #DIV/0! | AV6: =X6/AN6*100 -> #DIV/0! | AW6: =AA6/AN6*100 -> #DIV/0! | AX6: =AD6/AN6*100 -> #DIV/0! | AY6: =AG6/AN6*100 -> #DIV/0! | AZ6: =AJ6/AN6*100 -> #DIV/0!
A7: Total Abril | B7: =COUNTA(B6:B6) -> 1 | C7: =SUM(C6:C6) -> 381 | D7: =MIN(D6:D6) -> 45757 | E7: =MAX(E6:E6) -> 45776 | F7: =SUM(F6:F6) -> 86 | G7: =SUM(G6:G6) -> 0 | H7: =F7+G7 -> 86 | I7: =SUM(I6:I6) -> 0 | J7: =SUM(J6:J6) -> 0 | K7: =H7+I7+J7 -> 86 | L7: =SUM(L6:L6) -> 0 | M7: =SUM(M6:M6) -> 0 | N7: =SUM(N6:N6) -> 86 | O7: =SUM(O6:O6) -> 0 | P7: =SUM(P6:P6) -> 0 | Q7: =SUM(Q6:Q6) -> 54 | R7: =SUM(R6:R6) -> 0 | S7: =SUM(S6:S6) -> 31 | ... AJ7: =SUM(AJ6:AJ6) -> 0 | AK7: =P7+S7+V7+Y7+AB7+AE7+AH7 -> 1442 | AL7: =Q7+T7+W7+Z7+AC7+AF7+AI7 -> 512 | AM7: =AK7+AL7 -> 1954 | AN7: =R7+U7+X7+AA7+AD7+AG7+AJ7 -> 0 | AO7: =O7/H7*100 -> 0 | AP7: =AN7/H7*100 -> 0 | AQ7: =AN7/AM7*100 -> 0 | AR7: =AK7/AM7*100 -> 73.797339 | AS7: =AL7/AM7*100 -> 26.202661 | AT7: =R7/AN7*100 -> #DIV/0! | AU7: =U7/AN7*100 -> #DIV/0! | AV7: =X7/AN7*100 -> #DIV/0! | AW7: =AA7/AN7*100 -> #DIV/0! | AX7: =AD7/AN7*100 -> #DIV/0! | AY7: =AG7/AN7*100 -> #DIV/0! | AZ7: =AJ7/AN7*100 -> #DIV/0!
A8: Total | B8: =+B7 -> 1 | C8: =+C7 -> 381 | D8: =MIN(D6:D7) -> 45757 | E8: =MAX(E6:E7) -> 45776 | F8: =+F7 -> 86 | G8: =+G7 -> 0 | H8: =+H7 -> 86 | I8: =+I7 -> 0 | J8: =+J7 -> 0 | K8: =+K7 -> 86 | L8: =+L7 -> 0 | M8: =+M7 -> 0 | ... AJ8: =+AJ7 -> 0 | AK8: =P8+S8+V8+Y8+AB8+AE8+AH8 -> 1442 | AL8: =Q8+T8+W8+Z8+AC8+AF8+AI8 -> 512 | AM8: =AK8+AL8 -> 1954 | AN8: =R8+U8+X8+AA8+AD8+AG8+AJ8 -> 0 | AO8: =O8/H8*100 -> 0 | AP8: =AN8/H8*100 -> 0 | AQ8: =AN8/AM8*100 -> 0 | AR8: =AK8/AM8*100 -> 73.797339 | AS8: =AL8/AM8*100 -> 26.202661 | AT8: =R8/AN8*100 -> #DIV/0! | AU8: =U8/AN8*100 -> #DIV/0! | AV8: =X8/AN8*100 -> #DIV/0! | AW8: =AA8/AN8*100 -> #DIV/0! | AX8: =AD8/AN8*100 -> #DIV/0! | AY8: =AG8/AN8*100 -> #DIV/0! | AZ8: =AJ8/AN8*100 -> #DIV/0!
A9: Fuente: Estadistica programa ETV

Sheet Machareti
A1: ENCUESTA DE LARVARIA DE AEDES AEGYPTI POR COMUNIDAD - BARRIOS DE MACHARETI GESTION 2025
A3: Establecimiento | B3: Barrio / Comunidad | C3: Habitantaes protegidos | D3: FECHA | F3: PREDIOS | K3: TOTAL PREDIOS | L3: Manzanos | N3: VIVIENDAS | P3: Grupo A Depositos de Almacenamiento de Gran Volumen | V3: Grupo B Depositos de Transporte de Agua Moviles | Y3: Grupo C Depositos Fijos de Almacenamiento de Agua | AB3: Grupo D Depositos para Eliminacion | AH3: Grupo E Depositos Naturales | AK3: TOTAL | AO3: Indicadores | AT3: INDICADORES DE ENTOMOLOGICOS - TIPO RECIPIENTE
D4: Inicio | E4: Final | F4: INSPECCIONADAS | H4: TOTAL | I4: Cerradas | J4: Renuentes | L4: EVALUADAS | M4: FOCO AEDES | N4: CON FOCO | O4: FOCO AEDES | P4: A1 | S4: A2 | V4: B | Y4: C | AB4: D1 | AE4: D2 | AH4: E | AK4: Total Recipinetes Secos | AL4: Total Recipinetes Agua | AM4: Total Recipinetes | AN4: Total Recipinetes Positivos (+) | AO4: Entomologico | AR4: Recipiente | AT4: Grupo A Depositos de Almacenamiento de Gran Volumen | AV4: Grupo B Depositos de Transporte de Agua Moviles | AW4: Grupo C Depositos Fijos de Almacenamiento de Agua | AX4: Grupo D Depositos para Eliminacion | AZ4: Grupo E Depositos Naturales
F5: Vivienda | G5: T . Baldio | P5: S | Q5: A | R5: POSITIVOS (+) | S5: S | T5: A | U5: POSITIVOS (+) | V5: S | W5: A | X5: POSITIVOS (+) | Y5: S | Z5: A | AA5: POSITIVOS (+) | AB5: S | AC5: A | AD5: POSITIVOS (+) | AE5: S | AF5: A | AG5: POSITIVOS (+) | AH5: S | AI5: A | AJ5: POSITIVOS (+) | AO5: % Indice de Infestacion | AP5: % Indice Bretau | AQ5: % Indice Recipiente | AR5: % Recipientes secos | AS5: % Recipientes con agua | AT5: A1 | AU5: A2 | AV5: B | AW5: C | AX5: D1 | AY5: D2 | AZ5: E
A6: C.S. Machareti Santa Isabel | B6: Machareti | C6: =SUM(C7:C8) -> 967 | D6: =MIN(D7:D8) -> 45659 | E6: =MAX(E7:E8) -> 45674 | F6: =SUM(F7:F8) -> 329 | G6: =SUM(G7:G8) -> 0 | H6: =SUM(H7:H8) -> 329 | I6: =SUM(I7:I8) -> 14 | J6: =SUM(J7:J8) -> 0 | K6: =SUM(K7:K8) -> 343 | L6: =SUM(L7:L8) -> 0 | M6: =SUM(M7:M8) -> 0 | ... AJ6: =SUM(AJ7:AJ8) -> 0 | AK6: =P6+S6+V6+Y6+AB6+AE6+AH6 -> 301 | AL6: =Q6+T6+W6+Z6+AC6+AF6+AI6 -> 1189 | AM6: =AK6+AL6 -> 1490 | AN6: =R6+U6+X6+AA6+AD6+AG6+AJ6 -> 117 | AO6: =O6/H6*100 -> 20.972644 | AP6: =AN6/H6*100 -> 35.56231 | AQ6: =AN6/AM6*100 -> 7.852349 | AR6: =AK6/AM6*100 -> 20.201342 | AS6: =AL6/AM6*100 -> 79.798658 | AT6: =R6/AN6*100 -> 0 | AU6: =U6/AN6*100 -> 44.444444 | AV6: =X6/AN6*100 -> 29.91453 | AW6: =AA6/AN6*100 -> 9.4017094 | AX6: =AD6/AN6*100 -> 10.25641 | AY6: =AG6/AN6*100 -> 5.982906 | AZ6: =AJ6/AN6*100 -> 0
B7: Barrio Central | C7: 468 | D7: 45659 | E7: 45670 | F7: 158 | G7: 0 | H7: =F7+G7 -> 158 | I7: 8 | J7: 0 | K7: =H7+I7+J7 -> 166 | L7: 0 | M7: 0 | N7: 0 | O7: 42 | P7: 0 | Q7: 0 | R7: 0 | S7: 0 | T7: 358 | U7: 31 | V7: 7 | W7: 175 | X7: 26 | Y7: 1 | Z7: 56 | AA7: 10 | AB7: 6 | AC7: 98 | AD7: 10 | AE7: 54 | AF7: 30 | AG7: 2 | AH7: 0 | AI7: 0 | AJ7: 0 | AK7: =P7+S7+V7+Y7+AB7+AE7+AH7 -> 68 | AL7: =Q7+T7+W7+Z7+AC7+AF7+AI7 -> 717 | AM7: =AK7+AL7 -> 785 | AN7: =R7+U7+X7+AA7+AD7+AG7+AJ7 -> 79 | AO7: =O7/H7*100 -> 26.582278 | AP7: =AN7/H7*100 -> 50 | AQ7: =AN7/AM7*100 -> 10.063694 | AR7: =AK7/AM7*100 -> 8.6624204 | AS7: =AL7/AM7*100 -> 91.33758 | AT7: =R7/AN7*100 -> 0 | AU7: =U7/AN7*100 -> 39.240506 | AV7: =X7/AN7*100 -> 32.911392 | AW7: =AA7/AN7*100 -> 12.658228 | AX7: =AD7/AN7*100 -> 12.658228 | AY7: =AG7/AN7*100 -> 2.5316456 | AZ7: =AJ7/AN7*100 -> 0
B8: Barrio San Jose | C8: 499 | D8: 45670 | E8: 45674 | F8: 171 | G8: 0 | H8: =F8+G8 -> 171 | I8: 6 | J8: 0 | K8: =H8+I8+J8 -> 177 | L8: 0 | M8: 0 | N8: 0 | O8: 27 | P8: 0 | Q8: 0 | R8: 0 | S8: 0 | T8: 322 | U8: 21 | V8: 4 | W8: 100 | X8: 9 | Y8: 4 | Z8: 16 | AA8: 1 | AB8: 28 | AC8: 15 | AD8: 2 | AE8: 197 | AF8: 19 | AG8: 5 | AH8: 0 | AI8: 0 | AJ8: 0 | AK8: =P8+S8+V8+Y8+AB8+AE8+AH8 -> 233 | AL8: =Q8+T8+W8+Z8+AC8+AF8+AI8 -> 472 | AM8: =AK8+AL8 -> 705 | AN8: =R8+U8+X8+AA8+AD8+AG8+AJ8 -> 38 | AO8: =O8/H8*100 -> 15.789474 | AP8: =AN8/H8*100 -> 22.222222 | AQ8: =AN8/AM8*100 -> 5.3900709 | AR8: =AK8/AM8*100 -> 33.049645 | AS8: =AL8/AM8*100 -> 66.950355 | AT8: =R8/AN8*100 -> 0 | AU8: =U8/AN8*100 -> 55.263158 | AV8: =X8/AN8*100 -> 23.684211 | AW8: =AA8/AN8*100 -> 2.6315789 | AX8: =AD8/AN8*100 -> 5.2631579 | AY8: =AG8/AN8*100 -> 13.157895 | AZ8: =AJ8/AN8*100 -> 0
B9: Comunidad Tati | C9: 141 | D9: 45677 | E9: 45677 | F9: 44 | G9: 0 | H9: =F9+G9 -> 44 | I9: 1 | J9: 0 | K9: =H9+I9+J9 -> 45 | L9: 0 | M9: 0 | N9: 0 | O9: 4 | P9: 0 | Q9: 0 | R9: 0 | S9: 1 | T9: 65 | U9: 4 | V9: 0 | W9: 19 | X9: 0 | Y9: 0 | Z9: 7 | AA9: 0 | AB9: 0 | AC9: 3 | AD9: 0 | AE9: 5 | AF9: 25 | AG9: 0 | AH9: 0 | AI9: 0 | AJ9: 0 | AK9: =P9+S9+V9+Y9+AB9+AE9+AH9 -> 6 | AL9: =Q9+T9+W9+Z9+AC9+AF9+AI9 -> 119 | AM9: =AK9+AL9 -> 125 | AN9: =R9+U9+X9+AA9+AD9+AG9+AJ9 -> 4 | AO9: =O9/H9*100 -> 9.0909091 | AP9: =AN9/H9*100 -> 9.0909091 | AQ9: =AN9/AM9*100 -> 3.2 | AR9: =AK9/AM9*100 -> 4.8 | AS9: =AL9/AM9*100 -> 95.2 | AT9: =R9/AN9*100 -> 0 | AU9: =U9/AN9*100 -> 100 | AV9: =X9/AN9*100 -> 0 | AW9: =AA9/AN9*100 -> 0 | AX9: =AD9/AN9*100 -> 0 | AY9: =AG9/AN9*100 -> 0 | AZ9: =AJ9/AN9*100 -> 0
A10: C.S. Ivo | B10: Comunidad Ivo | C10: 32 | D10: 45674 | E10: 45674 | F10: 11 | G10: 0 | H10: =F10+G10 -> 11 | I10: 0 | J10: 0 | K10: =H10+I10+J10 -> 11 | L10: 0 | M10: 0 | N10: 0 | O10: 3 | P10: 0 | Q10: 0 | R10: 0 | S10: 0 | T10: 9 | U10: 4 | V10: 0 | W10: 23 | X10: 2 | Y10: 0 | Z10: 5 | AA10: 0 | AB10: 0 | AC10: 3 | AD10: 0 | AE10: 4 | AF10: 3 | AG10: 0 | AH10: 0 | AI10: 0 | AJ10: 0 | AK10: =P10+S10+V10+Y10+AB10+AE10+AH10 -> 4 | AL10: =Q10+T10+W10+Z10+AC10+AF10+AI10 -> 43 | AM10: =AK10+AL10 -> 47 | AN10: =R10+U10+X10+AA10+AD10+AG10+AJ10 -> 6 | AO10: =O10/H10*100 -> 27.272727 | AP10: =AN10/H10*100 -> 54.545455 | AQ10: =AN10/AM10*100 -> 12.765957 | AR10: =AK10/AM10*100 -> 8.5106383 | AS10: =AL10/AM10*100 -> 91.489362 | AT10: =R10/AN10*100 -> 0 | AU10: =U10/AN10*100 -> 66.666667 | AV10: =X10/AN10*100 -> 33.333333 | AW10: =AA10/AN10*100 -> 0 | AX10: =AD10/AN10*100 -> 0 | AY10: =AG10/AN10*100 -> 0 | AZ10: =AJ10/AN10*100 -> 0
A11: C.S. Tiguipa Estacion | B11: Comunidad Tiguipa Estacion | C11: 337 | D11: 45684 | E11: 45688 | F11: 150 | G11: 0 | H11: =F11+G11 -> 150 | I11: 5 | J11: 0 | K11: =H11+I11+J11 -> 155 | L11: 0 | M11: 0 | N11: 0 | O11: 25 | P11: 0 | Q11: 0 | R11: 0 | S11: 1 | T11: 209 | U11: 18 | V11: 0 | W11: 46 | X11: 9 | Y11: 2 | Z11: 38 | AA11: 5 | AB11: 10 | AC11: 41 | AD11: 10 | AE11: 112 | AF11: 48 | AG11: 0 | AH11: 0 | AI11: 0 | AJ11: 0 | AK11: =P11+S11+V11+Y11+AB11+AE11+AH11 -> 125 | AL11: =Q11+T11+W11+Z11+AC11+AF11+AI11 -> 382 | AM11: =AK11+AL11 -> 507 | AN11: =R11+U11+X11+AA11+AD11+AG11+AJ11 -> 42 | AO11: =O11/H11*100 -> 16.666667 | AP11: =AN11/H11*100 -> 28 | AQ11: =AN11/AM11*100 -> 8.2840237 | AR11: =AK11/AM11*100 -> 24.654832 | AS11: =AL11/AM11*100 -> 75.345168 | AT11: =R11/AN11*100 -> 0 | AU11: =U11/AN11*100 -> 42.857143 | AV11: =X11/AN11*100 -> 21.428571 | AW11: =AA11/AN11*100 -> 11.904762 | AX11: =AD11/AN11*100 -> 23.809524 | AY11: =AG11/AN11*100 -> 0 | AZ11: =AJ11/AN11*100 -> 0
A12: P.S. Tiguipa Pueblo | B12: Comunidad Tiguipa Pueblo | C12: 214 | D12: 45680 | E12: 45681 | F12: 87 | G12: 0 | H12: =F12+G12 -> 87 | I12: 1 | J12: 0 | K12: =H12+I12+J12 -> 88 | L12: 0 | M12: 0 | N12: 0 | O12: 17 | P12: 0 | Q12: 0 | R12: 0 | S12: 0 | T12: 124 | U12: 19 | V12: 0 | W12: 45 | X12: 4 | Y12: 0 | Z12: 8 | AA12: 2 | AB12: 5 | AC12: 16 | AD12: 6 | AE12: 81 | AF12: 34 | AG12: 1 | AH12: 0 | AI12: 0 | AJ12: 0 | AK12: =P12+S12+V12+Y12+AB12+AE12+AH12 -> 86 | AL12: =Q12+T12+W12+Z12+AC12+AF12+AI12 -> 227 | AM12: =AK12+AL12 -> 313 | AN12: =R12+U12+X12+AA12+AD12+AG12+AJ12 -> 32 | AO12: =O12/H12*100 -> 19.54023 | AP12: =AN12/H12*100 -> 36.781609 | AQ12: =AN12/AM12*100 -> 10.223642 | AR12: =AK12/AM12*100 -> 27.476038 | AS12: =AL12/AM12*100 -> 72.523962 | AT12: =R12/AN12*100 -> 0 | AU12: =U12/AN12*100 -> 59.375 | AV12: =X12/AN12*100 -> 12.5 | AW12: =AA12/AN12*100 -> 6.25 | AX12: =AD12/AN12*100 -> 18.75 | AY12: =AG12/AN12*100 -> 3.125 | AZ12: =AJ12/AN12*100 -> 0
A13: P.S. Tentami | B13: Comunidad Tentami | C13: 129 | D13: 45678 | E13: 45678 | F13: 41 | G13: 0 | H13: =F13+G13 -> 41 | I13: 0 | J13: 0 | K13: =H13+I13+J13 -> 41 | L13: 0 | M13: 0 | N13: 0 | O13: 3 | P13: 0 | Q13: 0 | R13: 0 | S13: 1 | T13: 48 | U13: 3 | V13: 8 | W13: 4 | X13: 0 | Y13: 0 | Z13: 4 | AA13: 0 | AB13: 0 | AC13: 4 | AD13: 0 | AE13: 1 | AF13: 11 | AG13: 0 | AH13: 0 | AI13: 0 | AJ13: 0 | AK13: =P13+S13+V13+Y13+AB13+AE13+AH13 -> 10 | AL13: =Q13+T13+W13+Z13+AC13+AF13+AI13 -> 71 | AM13: =AK13+AL13 -> 81 | AN13: =R13+U13+X13+AA13+AD13+AG13+AJ13 -> 3 | AO13: =O13/H13*100 -> 7.3170732 | AP13: =AN13/H13*100 -> 7.3170732 | AQ13: =AN13/AM13*100 -> 3.7037037 | AR13: =AK13/AM13*100 -> 12.345679 | AS13: =AL13/AM13*100 -> 87.654321 | AT13: =R13/AN13*100 -> 0 | AU13: =U13/AN13*100 -> 100 | AV13: =X13/AN13*100 -> 0 | AW13: =AA13/AN13*100 -> 0 | AX13: =AD13/AN13*100 -> 0 | AY13: =AG13/AN13*100 -> 0 | AZ13: =AJ13/AN13*100 -> 0
A14: Total Enero | B14: =COUNTA(B7:B13) -> 7 | C14: =SUM(C9:C13)+C6 -> 1820 | D14: =MIN(D7:D13) -> 45659 | E14: =MAX(E7:E13) -> 45688 | F14: =SUM(F9:F13)+F6 -> 662 | G14: =SUM(G9:G13)+G6 -> 0 | H14: =SUM(H9:H13)+H6 -> 662 | I14: =SUM(I9:I13)+I6 -> 21 | J14: =SUM(J9:J13)+J6 -> 0 | K14: =SUM(K9:K13)+K6 -> 683 | L14: =SUM(L9:L13)+L6 -> 0 | M14: =SUM(M9:M13)+M6 -> 0 | ... AJ14: =SUM(AJ9:AJ13)+AJ6 -> 0 | AK14: =P14+S14+V14+Y14+AB14+AE14+AH14 -> 532 | AL14: =Q14+T14+W14+Z14+AC14+AF14+AI14 -> 2031 | AM14: =AK14+AL14 -> 2563 | AN14: =R14+U14+X14+AA14+AD14+AG14+AJ14 -> 204 | AO14: =O14/H14*100 -> 18.277946 | AP14: =AN14/H14*100 -> 30.81571 | AQ14: =AN14/AM14*100 -> 7.9594226 | AR14: =AK14/AM14*100 -> 20.756925 | AS14: =AL14/AM14*100 -> 79.243075 | AT14: =R14/AN14*100 -> 0 | AU14: =U14/AN14*100 -> 49.019608 | AV14: =X14/AN14*100 -> 24.509804 | AW14: =AA14/AN14*100 -> 8.8235294 | AX14: =AD14/AN14*100 -> 13.72549 | AY14: =AG14/AN14*100 -> 3.9215686 | AZ14: =AJ14/AN14*100 -> 0
A15: C.S. Machareti | B15: Machareti | C15: =C16 -> 100 | D15: 45715 | E15: 45715 | F15: =F16 -> 41 | G15: =G16 -> 0 | H15: =H16 -> 41 | I15: =I16 -> 0 | J15: =J16 -> 0 | K15: =K16 -> 41 | L15: =L16 -> 0 | M15: =M16 -> 0 | ... AJ15: =AJ16 -> 0 | AK15: =P15+S15+V15+Y15+AB15+AE15+AH15 -> 94 | AL15: =Q15+T15+W15+Z15+AC15+AF15+AI15 -> 136 | AM15: =AK15+AL15 -> 230 | AN15: =R15+U15+X15+AA15+AD15+AG15+AJ15 -> 19 | AO15: =O15/H15*100 -> 26.829268 | AP15: =AN15/H15*100 -> 46.341463 | AQ15: =AN15/AM15*100 -> 8.2608696 | AR15: =AK15/AM15*100 -> 40.869565 | AS15: =AL15/AM15*100 -> 59.130435 | AT15: =R15/AN15*100 -> 0 | AU15: =U15/AN15*100 -> 31.578947 | AV15: =X15/AN15*100 -> 10.526316 | AW15: =AA15/AN15*100 -> 26.315789 | AX15: =AD15/AN15*100 -> 26.315789 | AY15: =AG15/AN15*100 -> 5.2631579 | AZ15: =AJ15/AN15*100 -> 0
B16: Barrio Virgen del Carmen | C16: 100 | D16: 45715 | E16: 45715 | F16: 41 | G16: 0 | H16: =F16+G16 -> 41 | I16: 0 | J16: 0 | K16: =H16+I16+J16 -> 41 | L16: 0 | M16: 0 | N16: 41 | O16: 11 | P16: 0 | Q16: 3 | R16: 0 | S16: 1 | T16: 60 | U16: 6 | V16: 0 | W16: 18 | X16: 2 | Y16: 0 | Z16: 17 | AA16: 5 | AB16: 4 | AC16: 11 | AD16: 5 | AE16: 89 | AF16: 27 | AG16: 1 | AH16: 0 | AI16: 0 | AJ16: 0 | AK16: =P16+S16+V16+Y16+AB16+AE16+AH16 -> 94 | AL16: =Q16+T16+W16+Z16+AC16+AF16+AI16 -> 136 | AM16: =AK16+AL16 -> 230 | AN16: =R16+U16+X16+AA16+AD16+AG16+AJ16 -> 19 | AO16: =O16/H16*100 -> 26.829268 | AP16: =AN16/H16*100 -> 46.341463 | AQ16: =AN16/AM16*100 -> 8.2608696 | AR16: =AK16/AM16*100 -> 40.869565 | AS16: =AL16/AM16*100 -> 59.130435 | AT16: =R16/AN16*100 -> 0 | AU16: =U16/AN16*100 -> 31.578947 | AV16: =X16/AN16*100 -> 10.526316 | AW16: =AA16/AN16*100 -> 26.315789 | AX16: =AD16/AN16*100 -> 26.315789 | AY16: =AG16/AN16*100 -> 5.2631579 | AZ16: =AJ16/AN16*100 -> 0
A17: P.S. Carandayti | B17: Comunidad Carandayti | C17: 273 | D17: 45702 | E17: 45706 | F17: 95 | G17: 0 | H17: =F17+G17 -> 95 | I17: 0 | J17: 0 | K17: =H17+I17+J17 -> 95 | L17: 0 | M17: 0 | N17: 95 | O17: 35 | P17: 3 | Q17: 6 | R17: 0 | S17: 19 | T17: 173 | U17: 41 | V17: 8 | W17: 17 | X17: 7 | Y17: 1 | Z17: 9 | AA17: 2 | AB17: 59 | AC17: 12 | AD17: 7 | AE17: 254 | AF17: 4 | AG17: 2 | AH17: 0 | AI17: 0 | AJ17: 0 | AK17: =P17+S17+V17+Y17+AB17+AE17+AH17 -> 344 | AL17: =Q17+T17+W17+Z17+AC17+AF17+AI17 -> 221 | AM17: =AK17+AL17 -> 565 | AN17: =R17+U17+X17+AA17+AD17+AG17+AJ17 -> 59 | AO17: =O17/H17*100 -> 36.842105 | AP17: =AN17/H17*100 -> 62.105263 | AQ17: =AN17/AM17*100 -> 10.442478 | AR17: =AK17/AM17*100 -> 60.884956 | AS17: =AL17/AM17*100 -> 39.115044 | AT17: =R17/AN17*100 -> 0 | AU17: =U17/AN17*100 -> 69.491525 | AV17: =X17/AN17*100 -> 11.864407 | AW17: =AA17/AN17*100 -> 3.3898305 | AX17: =AD17/AN17*100 -> 11.864407 | AY17: =AG17/AN17*100 -> 3.3898305 | AZ17: =AJ17/AN17*100 -> 0
A18: C.S. Tiguipa Estacion | B18: Comunidad Tiguipa Estacion | C18: 143 | D18: 45693 | E18: 45695 | F18: 57 | G18: 0 | H18: =F18+G18 -> 57 | I18: 5 | J18: 0 | K18: =H18+I18+J18 -> 62 | L18: 0 | M18: 0 | N18: 57 | O18: 15 | P18: 0 | Q18: 1 | R18: 0 | S18: 2 | T18: 76 | U18: 8 | V18: 5 | W18: 28 | X18: 8 | Y18: 7 | Z18: 12 | AA18: 4 | AB18: 12 | AC18: 18 | AD18: 10 | AE18: 28 | AF18: 123 | AG18: 0 | AH18: 0 | AI18: 0 | AJ18: 0 | AK18: =P18+S18+V18+Y18+AB18+AE18+AH18 -> 54 | AL18: =Q18+T18+W18+Z18+AC18+AF18+AI18 -> 258 | AM18: =AK18+AL18 -> 312 | AN18: =R18+U18+X18+AA18+AD18+AG18+AJ18 -> 30 | AO18: =O18/H18*100 -> 26.315789 | AP18: =AN18/H18*100 -> 52.631579 | AQ18: =AN18/AM18*100 -> 9.6153846 | AR18: =AK18/AM18*100 -> 17.307692 | AS18: =AL18/AM18*100 -> 82.692308 | AT18: =R18/AN18*100 -> 0 | AU18: =U18/AN18*100 -> 26.666667 | AV18: =X18/AN18*100 -> 26.666667 | AW18: =AA18/AN18*100 -> 13.333333 | AX18: =AD18/AN18*100 -> 33.333333 | AY18: =AG18/AN18*100 -> 0 | AZ18: =AJ18/AN18*100 -> 0
A19: P.S. Camatini | B19: Comunidad Camatindi | C19: 305 | D19: 45698 | E19: 45701 | F19: 157 | G19: 0 | H19: =F19+G19 -> 157 | I19: 0 | J19: 0 | K19: =H19+I19+J19 -> 157 | L19: 0 | M19: 0 | N19: 157 | O19: 33 | P19: 0 | Q19: 3 | R19: 1 | S19: 9 | T19: 53 | U19: 12 | V19: 28 | W19: 21 | X19: 10 | Y19: 1 | Z19: 64 | AA19: 13 | AB19: 44 | AC19: 15 | AD19: 9 | AE19: 111 | AF19: 77 | AG19: 5 | AH19: 0 | AI19: 1 | AJ19: 1 | AK19: =P19+S19+V19+Y19+AB19+AE19+AH19 -> 193 | AL19: =Q19+T19+W19+Z19+AC19+AF19+AI19 -> 234 | AM19: =AK19+AL19 -> 427 | AN19: =R19+U19+X19+AA19+AD19+AG19+AJ19 -> 51 | AO19: =O19/H19*100 -> 21.019108 | AP19: =AN19/H19*100 -> 32.484076 | AQ19: =AN19/AM19*100 -> 11.943794 | AR19: =AK19/AM19*100 -> 45.199063 | AS19: =AL19/AM19*100 -> 54.800937 | AT19: =R19/AN19*100 -> 1.9607843 | AU19: =U19/AN19*100 -> 23.529412 | AV19: =X19/AN19*100 -> 19.607843 | AW19: =AA19/AN19*100 -> 25.490196 | AX19: =AD19/AN19*100 -> 17.647059 | AY19: =AG19/AN19*100 -> 9.8039216 | AZ19: =AJ19/AN19*100 -> 1.9607843
A20: Total Febrero | B20: =COUNTA(B16:B19) -> 4 | C20: =SUM(C17:C19)+C15 -> 821 | D20: =MIN(D16:D19) -> 45693 | E20: =MAX(E16:E19) -> 45715 | F20: =SUM(F17:F19)+F15 -> 350 | G20: =SUM(G17:G19)+G15 -> 0 | H20: =SUM(H17:H19)+H15 -> 350 | I20: =SUM(I17:I19)+I15 -> 5 | J20: =SUM(J17:J19)+J15 -> 0 | K20: =SUM(K17:K19)+K15 -> 355 | L20: =SUM(L17:L19)+L15 -> 0 | M20: =SUM(M17:M19)+M15 -> 0 | ... AJ20: =SUM(AJ17:AJ19)+AJ15 -> 1 | AK20: =P20+S20+V20+Y20+AB20+AE20+AH20 -> 685 | AL20: =Q20+T20+W20+Z20+AC20+AF20+AI20 -> 849 | AM20: =AK20+AL20 -> 1534 | AN20: =R20+U20+X20+AA20+AD20+AG20+AJ20 -> 159 | AO20: =O20/H20*100 -> 26.857143 | AP20: =AN20/H20*100 -> 45.428571 | AQ20: =AN20/AM20*100 -> 10.365059 | AR20: =AK20/AM20*100 -> 44.654498 | AS20: =AL20/AM20*100 -> 55.345502 | AT20: =R20/AN20*100 -> 0.62893082 | AU20: =U20/AN20*100 -> 42.138365 | AV20: =X20/AN20*100 -> 16.981132 | AW20: =AA20/AN20*100 -> 15.09434 | AX20: =AD20/AN20*100 -> 19.496855 | AY20: =AG20/AN20*100 -> 5.0314465 | AZ20: =AJ20/AN20*100 -> 0.62893082
A21: C.S. Machareti | B21: Machareti | C21: =SUM(C22:C23) -> 790 | D21: =MIN(D22:D23) -> 45733 | E21: =MAX(E22:E23) -> 45747 | F21: =SUM(F22:F23) -> 251 | G21: =SUM(G22:G23) -> 0 | H21: =SUM(H22:H23) -> 251 | I21: =SUM(I22:I23) -> 0 | J21: =SUM(J22:J23) -> 0 | K21: =SUM(K22:K23) -> 251 | L21: =SUM(L22:L23) -> 0 | M21: =SUM(M22:M23) -> 0 | ... AJ21: =SUM(AJ22:AJ23) -> 0 | AK21: =P21+S21+V21+Y21+AB21+AE21+AH21 -> 274 | AL21: =Q21+T21+W21+Z21+AC21+AF21+AI21 -> 928 | AM21: =AK21+AL21 -> 1202 | AN21: =R21+U21+X21+AA21+AD21+AG21+AJ21 -> 166 | AO21: =O21/H21*100 -> 36.25498 | AP21: =AN21/H21*100 -> 66.135458 | AQ21: =AN21/AM21*100 -> 13.810316 | AR21: =AK21/AM21*100 -> 22.795341 | AS21: =AL21/AM21*100 -> 77.204659 | AT21: =R21/AN21*100 -> 0 | AU21: =U21/AN21*100 -> 36.144578 | AV21: =X21/AN21*100 -> 12.650602 | AW21: =AA21/AN21*100 -> 18.072289 | AX21: =AD21/AN21*100 -> 20.481928 | AY21: =AG21/AN21*100 -> 12.650602 | AZ21: =AJ21/AN21*100 -> 0
B22: Barrio Virgen Del Carmen | C22: 470 | D22: 45733 | E22: 45737 | F22: 141 | G22: 0 | H22: =F22+G22 -> 141 | I22: 0 | J22: 0 | K22: =H22+I22+J22 -> 141 | L22: 0 | M22: 0 | N22: 141 | O22: 38 | P22: 0 | Q22: 1 | R22: 0 | S22: 0 | T22: 279 | U22: 23 | V22: 0 | W22: 75 | X22: 5 | Y22: 0 | Z22: 59 | AA22: 15 | AB22: 6 | AC22: 46 | AD22: 14 | AE22: 198 | AF22: 36 | AG22: 6 | AH22: 0 | AI22: 0 | AJ22: 0 | AK22: =P22+S22+V22+Y22+AB22+AE22+AH22 -> 204 | AL22: =Q22+T22+W22+Z22+AC22+AF22+AI22 -> 496 | AM22: =AK22+AL22 -> 700 | AN22: =R22+U22+X22+AA22+AD22+AG22+AJ22 -> 63 | AO22: =O22/H22*100 -> 26.950355 | AP22: =AN22/H22*100 -> 44.680851 | AQ22: =AN22/AM22*100 -> 9 | AR22: =AK22/AM22*100 -> 29.142857 | AS22: =AL22/AM22*100 -> 70.857143 | AT22: =R22/AN22*100 -> 0 | AU22: =U22/AN22*100 -> 36.507937 | AV22: =X22/AN22*100 -> 7.9365079 | AW22: =AA22/AN22*100 -> 23.809524 | AX22: =AD22/AN22*100 -> 22.222222 | AY22: =AG22/AN22*100 -> 9.5238095 | AZ22: =AJ22/AN22*100 -> 0
B23: Barrio Central | C23: 320 | D23: 45740 | E23: 45747 | F23: 110 | G23: 0 | H23: =F23+G23 -> 110 | I23: 0 | J23: 0 | K23: =H23+I23+J23 -> 110 | L23: 0 | M23: 0 | N23: 110 | O23: 53 | P23: 0 | Q23: 0 | R23: 0 | S23: 4 | T23: 214 | U23: 37 | V23: 0 | W23: 89 | X23: 16 | Y23: 0 | Z23: 45 | AA23: 15 | AB23: 0 | AC23: 39 | AD23: 20 | AE23: 66 | AF23: 45 | AG23: 15 | AH23: 0 | AI23: 0 | AJ23: 0 | AK23: =P23+S23+V23+Y23+AB23+AE23+AH23 -> 70 | AL23: =Q23+T23+W23+Z23+AC23+AF23+AI23 -> 432 | AM23: =AK23+AL23 -> 502 | AN23: =R23+U23+X23+AA23+AD23+AG23+AJ23 -> 103 | AO23: =O23/H23*100 -> 48.181818 | AP23: =AN23/H23*100 -> 93.636364 | AQ23: =AN23/AM23*100 -> 20.517928 | AR23: =AK23/AM23*100 -> 13.944223 | AS23: =AL23/AM23*100 -> 86.055777 | AT23: =R23/AN23*100 -> 0 | AU23: =U23/AN23*100 -> 35.92233 | AV23: =X23/AN23*100 -> 15.533981 | AW23: =AA23/AN23*100 -> 14.563107 | AX23: =AD23/AN23*100 -> 19.417476 | AY23: =AG23/AN23*100 -> 14.563107 | AZ23: =AJ23/AN23*100 -> 0
A24: P.S. Carandayti | B24: Comunidad Carandayti | C24: 265 | D24: 45724 | E24: 45728 | F24: 116 | G24: 0 | H24: =F24+G24 -> 116 | I24: 5 | J24: 0 | K24: =H24+I24+J24 -> 121 | L24: 0 | M24: 0 | N24: 116 | O24: 12 | P24: 0 | Q24: 0 | R24: 0 | S24: 7 | T24: 213 | U24: 7 | V24: 0 | W24: 68 | X24: 5 | Y24: 1 | Z24: 36 | AA24: 1 | AB24: 85 | AC24: 33 | AD24: 0 | AE24: 345 | AF24: 246 | AG24: 1 | AH24: 0 | AI24: 0 | AJ24: 0 | AK24: =P24+S24+V24+Y24+AB24+AE24+AH24 -> 438 | AL24: =Q24+T24+W24+Z24+AC24+AF24+AI24 -> 596 | AM24: =AK24+AL24 -> 1034 | AN24: =R24+U24+X24+AA24+AD24+AG24+AJ24 -> 14 | AO24: =O24/H24*100 -> 10.344828 | AP24: =AN24/H24*100 -> 12.068966 | AQ24: =AN24/AM24*100 -> 1.3539652 | AR24: =AK24/AM24*100 -> 42.359768 | AS24: =AL24/AM24*100 -> 57.640232 | AT24: =R24/AN24*100 -> 0 | AU24: =U24/AN24*100 -> 50 | AV24: =X24/AN24*100 -> 35.714286 | AW24: =AA24/AN24*100 -> 7.1428571 | AX24: =AD24/AN24*100 -> 0 | AY24: =AG24/AN24*100 -> 7.1428571 | AZ24: =AJ24/AN24*100 -> 0
A25: C.S. Ivo | B25: Comunidad Ivo | C25: 103 | D25: 45743 | E25: 45743 | F25: 38 | G25: 0 | H25: =F25+G25 -> 38 | I25: 0 | J25: 0 | K25: =H25+I25+J25 -> 38 | L25: 0 | M25: 0 | N25: 38 | O25: 15 | P25: 0 | Q25: 0 | R25: 0 | S25: 0 | T25: 65 | U25: 22 | V25: 0 | W25: 1 | X25: 0 | Y25: 0 | Z25: 2 | AA25: 1 | AB25: 0 | AC25: 6 | AD25: 0 | AE25: 10 | AF25: 1 | AG25: 0 | AH25: 0 | AI25: 0 | AJ25: 0 | AK25: =P25+S25+V25+Y25+AB25+AE25+AH25 -> 10 | AL25: =Q25+T25+W25+Z25+AC25+AF25+AI25 -> 75 | AM25: =AK25+AL25 -> 85 | AN25: =R25+U25+X25+AA25+AD25+AG25+AJ25 -> 23 | AO25: =O25/H25*100 -> 39.473684 | AP25: =AN25/H25*100 -> 60.526316 | AQ25: =AN25/AM25*100 -> 27.058824 | AR25: =AK25/AM25*100 -> 11.764706 | AS25: =AL25/AM25*100 -> 88.235294 | AT25: =R25/AN25*100 -> 0 | AU25: =U25/AN25*100 -> 95.652174 | AV25: =X25/AN25*100 -> 0 | AW25: =AA25/AN25*100 -> 4.3478261 | AX25: =AD25/AN25*100 -> 0 | AY25: =AG25/AN25*100 -> 0 | AZ25: =AJ25/AN25*100 -> 0
A26: Total Marzo | B26: 4 | C26: =SUM(C24:C25)+C21 -> 1158 | D26: =MIN(D22:D25) -> 45724 | E26: =MAX(E22:E25) -> 45747 | F26: =SUM(F24:F25)+F21 -> 405 | G26: =SUM(G24:G25)+G21 -> 0 | H26: =SUM(H24:H25)+H21 -> 405 | I26: =SUM(I24:I25)+I21 -> 5 | J26: =SUM(J24:J25)+J21 -> 0 | K26: =SUM(K24:K25)+K21 -> 410 | L26: =SUM(L24:L25)+L21 -> 0 | M26: =SUM(M24:M25)+M21 -> 0 | ... AJ26: =SUM(AJ24:AJ25)+AJ21 -> 0 | AK26: =P26+S26+V26+Y26+AB26+AE26+AH26 -> 722 | AL26: =Q26+T26+W26+Z26+AC26+AF26+AI26 -> 1599 | AM26: =AK26+AL26 -> 2321 | AN26: =R26+U26+X26+AA26+AD26+AG26+AJ26 -> 203 | AO26: =O26/H26*100 -> 29.135802 | AP26: =AN26/H26*100 -> 50.123457 | AQ26: =AN26/AM26*100 -> 8.7462301 | AR26: =AK26/AM26*100 -> 31.107281 | AS26: =AL26/AM26*100 -> 68.892719 | AT26: =R26/AN26*100 -> 0 | AU26: =U26/AN26*100 -> 43.842365 | AV26: =X26/AN26*100 -> 12.807882 | AW26: =AA26/AN26*100 -> 15.763547 | AX26: =AD26/AN26*100 -> 16.748768 | AY26: =AG26/AN26*100 -> 10.837438 | AZ26: =AJ26/AN26*100 -> 0
A27: C.S. Machareti | B27: Machareti | C27: =SUM(C28:C29) -> 611 | D27: =MIN(D28:D29) -> 45749 | E27: =MAX(E28:E29) -> 45756 | F27: =SUM(F28:F29) -> 189 | G27: =SUM(G28:G29) -> 0 | H27: =SUM(H28:H29) -> 189 | I27: =SUM(I28:I29) -> 0 | J27: =SUM(J28:J29) -> 0 | K27: =SUM(K28:K29) -> 189 | L27: =SUM(L28:L29) -> 0 | M27: =SUM(M28:M29) -> 0 | ... AJ27: =SUM(AJ28:AJ29) -> 0 | AK27: =P27+S27+V27+Y27+AB27+AE27+AH27 -> 219 | AL27: =Q27+T27+W27+Z27+AC27+AF27+AI27 -> 596 | AM27: =AK27+AL27 -> 815 | AN27: =R27+U27+X27+AA27+AD27+AG27+AJ27 -> 95 | AO27: =O27/H27*100 -> 33.862434 | AP27: =AN27/H27*100 -> 50.26455 | AQ27: =AN27/AM27*100 -> 11.656442 | AR27: =AK27/AM27*100 -> 26.871166 | AS27: =AL27/AM27*100 -> 73.128834 | AT27: =R27/AN27*100 -> 0 | AU27: =U27/AN27*100 -> 35.789474 | AV27: =X27/AN27*100 -> 12.631579 | AW27: =AA27/AN27*100 -> 11.578947 | AX27: =AD27/AN27*100 -> 15.789474 | AY27: =AG27/AN27*100 -> 24.210526 | AZ27: =AJ27/AN27*100 -> 0
B28: Barrio Central | C28: 148 | D28: 45749 | E28: 45749 | F28: 41 | G28: 0 | H28: =F28+G28 -> 41 | I28: 0 | J28: 0 | K28: =H28+I28+J28 -> 41 | L28: 0 | M28: 0 | N28: 41 | O28: 16 | P28: 0 | Q28: 0 | R28: 0 | S28: 5 | T28: 103 | U28: 11 | V28: 0 | W28: 19 | X28: 0 | Y28: 0 | Z28: 5 | AA28: 5 | AB28: 12 | AC28: 14 | AD28: 6 | AE28: 31 | AF28: 17 | AG28: 10 | AH28: 0 | AI28: 0 | AJ28: 0 | AK28: =P28+S28+V28+Y28+AB28+AE28+AH28 -> 48 | AL28: =Q28+T28+W28+Z28+AC28+AF28+AI28 -> 158 | AM28: =AK28+AL28 -> 206 | AN28: =R28+U28+X28+AA28+AD28+AG28+AJ28 -> 32 | AO28: =O28/H28*100 -> 39.02439 | AP28: =AN28/H28*100 -> 78.04878 | AQ28: =AN28/AM28*100 -> 15.533981 | AR28: =AK28/AM28*100 -> 23.300971 | AS28: =AL28/AM28*100 -> 76.699029 | AT28: =R28/AN28*100 -> 0 | AU28: =U28/AN28*100 -> 34.375 | AV28: =X28/AN28*100 -> 0 | AW28: =AA28/AN28*100 -> 15.625 | AX28: =AD28/AN28*100 -> 18.75 | AY28: =AG28/AN28*100 -> 31.25 | AZ28: =AJ28/AN28*100 -> 0
B29: Barrio San Jose | C29: 463 | D29: 45750 | E29: 45756 | F29: 148 | G29: 0 | H29: =F29+G29 -> 148 | I29: 0 | J29: 0 | K29: =H29+I29+J29 -> 148 | L29: 0 | M29: 0 | N29: 148 | O29: 48 | P29: 0 | Q29: 0 | R29: 0 | S29: 4 | T29: 272 | U29: 23 | V29: 1 | W29: 68 | X29: 12 | Y29: 0 | Z29: 20 | AA29: 6 | AB29: 33 | AC29: 18 | AD29: 9 | AE29: 133 | AF29: 60 | AG29: 13 | AH29: 0 | AI29: 0 | AJ29: 0 | AK29: =P29+S29+V29+Y29+AB29+AE29+AH29 -> 171 | AL29: =Q29+T29+W29+Z29+AC29+AF29+AI29 -> 438 | AM29: =AK29+AL29 -> 609 | AN29: =R29+U29+X29+AA29+AD29+AG29+AJ29 -> 63 | AO29: =O29/H29*100 -> 32.432432 | AP29: =AN29/H29*100 -> 42.567568 | AQ29: =AN29/AM29*100 -> 10.344828 | AR29: =AK29/AM29*100 -> 28.078818 | AS29: =AL29/AM29*100 -> 71.921182 | AT29: =R29/AN29*100 -> 0 | AU29: =U29/AN29*100 -> 36.507937 | AV29: =X29/AN29*100 -> 19.047619 | AW29: =AA29/AN29*100 -> 9.5238095 | AX29: =AD29/AN29*100 -> 14.285714 | AY29: =AG29/AN29*100 -> 20.634921 | AZ29: =AJ29/AN29*100 -> 0
B30: Comunidad Estacion Machareti | C30: 74 | D30: 45758 | E30: 45758 | F30: 36 | G30: 0 | H30: =F30+G30 -> 36 | I30: 0 | J30: 0 | K30: =H30+I30+J30 -> 36 | L30: 0 | M30: 0 | N30: 36 | O30: 13 | P30: 0 | Q30: 0 | R30: 0 | S30: 0 | T30: 32 | U30: 16 | V30: 0 | W30: 12 | X30: 5 | Y30: 0 | Z30: 1 | AA30: 0 | AB30: 2 | AC30: 1 | AD30: 0 | AE30: 24 | AF30: 23 | AG30: 8 | AH30: 0 | AI30: 0 | AJ30: 0 | AK30: =P30+S30+V30+Y30+AB30+AE30+AH30 -> 26 | AL30: =Q30+T30+W30+Z30+AC30+AF30+AI30 -> 69 | AM30: =AK30+AL30 -> 95 | AN30: =R30+U30+X30+AA30+AD30+AG30+AJ30 -> 29 | AO30: =O30/H30*100 -> 36.111111 | AP30: =AN30/H30*100 -> 80.555556 | AQ30: =AN30/AM30*100 -> 30.526316 | AR30: =AK30/AM30*100 -> 27.368421 | AS30: =AL30/AM30*100 -> 72.631579 | AT30: =R30/AN30*100 -> 0 | AU30: =U30/AN30*100 -> 55.172414 | AV30: =X30/AN30*100 -> 17.241379 | AW30: =AA30/AN30*100 -> 0 | AX30: =AD30/AN30*100 -> 0 | AY30: =AG30/AN30*100 -> 27.586207 | AZ30: =AJ30/AN30*100 -> 0
B31: Comunidad Tati | C31: 126 | D31: 45757 | E31: 45761 | F31: 42 | G31: 0 | H31: =F31+G31 -> 42 | I31: 0 | J31: 0 | K31: =H31+I31+J31 -> 42 | L31: 0 | M31: 0 | N31: 42 | O31: 9 | P31: 0 | Q31: 0 | R31: 0 | S31: 0 | T31: 74 | U31: 9 | V31: 0 | W31: 0 | X31: 0 | Y31: 0 | Z31: 5 | AA31: 1 | AB31: 0 | AC31: 1 | AD31: 0 | AE31: 33 | AF31: 3 | AG31: 2 | AH31: 0 | AI31: 0 | AJ31: 0 | AK31: =P31+S31+V31+Y31+AB31+AE31+AH31 -> 33 | AL31: =Q31+T31+W31+Z31+AC31+AF31+AI31 -> 83 | AM31: =AK31+AL31 -> 116 | AN31: =R31+U31+X31+AA31+AD31+AG31+AJ31 -> 12 | AO31: =O31/H31*100 -> 21.428571 | AP31: =AN31/H31*100 -> 28.571429 | AQ31: =AN31/AM31*100 -> 10.344828 | AR31: =AK31/AM31*100 -> 28.448276 | AS31: =AL31/AM31*100 -> 71.551724 | AT31: =R31/AN31*100 -> 0 | AU31: =U31/AN31*100 -> 75 | AV31: =X31/AN31*100 -> 0 | AW31: =AA31/AN31*100 -> 8.3333333 | AX31: =AD31/AN31*100 -> 0 | AY31: =AG31/AN31*100 -> 16.666667 | AZ31: =AJ31/AN31*100 -> 0
A32: P.S. Tiguipa Pueblo | B32: Comunidad Tiguipa Pueblo | C32: 158 | D32: 45776 | E32: 45777 | F32: 65 | G32: 0 | H32: =F32+G32 -> 65 | I32: 0 | J32: 0 | K32: =H32+I32+J32 -> 65 | L32: 0 | M32: 0 | N32: 65 | O32: 17 | P32: 0 | Q32: 0 | R32: 0 | S32: 1 | T32: 73 | U32: 8 | V32: 0 | W32: 27 | X32: 6 | Y32: 0 | Z32: 16 | AA32: 4 | AB32: 0 | AC32: 29 | AD32: 16 | AE32: 38 | AF32: 45 | AG32: 13 | AH32: 0 | AI32: 0 | AJ32: 0 | AK32: =P32+S32+V32+Y32+AB32+AE32+AH32 -> 39 | AL32: =Q32+T32+W32+Z32+AC32+AF32+AI32 -> 190 | AM32: =AK32+AL32 -> 229 | AN32: =R32+U32+X32+AA32+AD32+AG32+AJ32 -> 47 | AO32: =O32/H32*100 -> 26.153846 | AP32: =AN32/H32*100 -> 72.307692 | AQ32: =AN32/AM32*100 -> 20.524017 | AR32: =AK32/AM32*100 -> 17.030568 | AS32: =AL32/AM32*100 -> 82.969432 | AT32: =R32/AN32*100 -> 0 | AU32: =U32/AN32*100 -> 17.021277 | AV32: =X32/AN32*100 -> 12.765957 | AW32: =AA32/AN32*100 -> 8.5106383 | AX32: =AD32/AN32*100 -> 34.042553 | AY32: =AG32/AN32*100 -> 27.659574 | AZ32: =AJ32/AN32*100 -> 0
A33: C.S. Ivo | B33: Comunidad Ivo | C33: 787 | D33: 45762 | E33: 45762 | F33: 40 | G33: 0 | H33: =F33+G33 -> 40 | I33: 0 | J33: 0 | K33: =H33+I33+J33 -> 40 | L33: 0 | M33: 0 | N33: 40 | O33: 9 | P33: 0 | Q33: 0 | R33: 0 | S33: 0 | T33: 34 | U33: 6 | V33: 0 | W33: 4 | X33: 1 | Y33: 0 | Z33: 18 | AA33: 10 | AB33: 31 | AC33: 70 | AD33: 27 | AE33: 687 | AF33: 53 | AG33: 2 | AH33: 0 | AI33: 0 | AJ33: 0 | AK33: =P33+S33+V33+Y33+AB33+AE33+AH33 -> 718 | AL33: =Q33+T33+W33+Z33+AC33+AF33+AI33 -> 179 | AM33: =AK33+AL33 -> 897 | AN33: =R33+U33+X33+AA33+AD33+AG33+AJ33 -> 46 | AO33: =O33/H33*100 -> 22.5 | AP33: =AN33/H33*100 -> 115 | AQ33: =AN33/AM33*100 -> 5.1282051 | AR33: =AK33/AM33*100 -> 80.044593 | AS33: =AL33/AM33*100 -> 19.955407 | AT33: =R33/AN33*100 -> 0 | AU33: =U33/AN33*100 -> 13.043478 | AV33: =X33/AN33*100 -> 2.173913 | AW33: =AA33/AN33*100 -> 21.73913 | AX33: =AD33/AN33*100 -> 58.695652 | AY33: =AG33/AN33*100 -> 4.3478261 | AZ33: =AJ33/AN33*100 -> 0
A34: Total Abril | B34: 6 | C34: =SUM(C30:C33)+C27 -> 1756 | D34: =MIN(D27:D33) -> 45749 | E34: =MAX(E27:E33) -> 45777 | F34: =SUM(F30:F33)+F27 -> 372 | G34: =SUM(G30:G33)+G27 -> 0 | H34: =SUM(H30:H33)+H27 -> 372 | I34: =SUM(I30:I33)+I27 -> 0 | J34: =SUM(J30:J33)+J27 -> 0 | K34: =SUM(K30:K33)+K27 -> 372 | L34: =SUM(L30:L33)+L27 -> 0 | M34: =SUM(M30:M33)+M27 -> 0 | ... AJ34: =SUM(AJ30:AJ33)+AJ27 -> 0 | AK34: =P34+S34+V34+Y34+AB34+AE34+AH34 -> 1035 | AL34: =Q34+T34+W34+Z34+AC34+AF34+AI34 -> 1117 | AM34: =AK34+AL34 -> 2152 | AN34: =R34+U34+X34+AA34+AD34+AG34+AJ34 -> 229 | AO34: =O34/H34*100 -> 30.107527 | AP34: =AN34/H34*100 -> 61.55914 | AQ34: =AN34/AM34*100 -> 10.641264 | AR34: =AK34/AM34*100 -> 48.094796 | AS34: =AL34/AM34*100 -> 51.905204 | AT34: =R34/AN34*100 -> 0 | AU34: =U34/AN34*100 -> 31.877729 | AV34: =X34/AN34*100 -> 10.480349 | AW34: =AA34/AN34*100 -> 11.353712 | AX34: =AD34/AN34*100 -> 25.327511 | AY34: =AG34/AN34*100 -> 20.960699 | AZ34: =AJ34/AN34*100 -> 0
A35: P.S. Carandayti | B35: Comunidad Carandayti | C35: 215 | D35: 05/052025 | E35: 45783 | F35: 68 | G35: 0 | H35: =F35+G35 -> 68 | I35: 0 | J35: 0 | K35: =H35+I35+J35 -> 68 | L35: 0 | M35: 0 | N35: 68 | O35: 16 | P35: 0 | Q35: 0 | R35: 0 | S35: 0 | T35: 151 | U35: 11 | V35: 0 | W35: 26 | X35: 6 | Y35: 0 | Z35: 5 | AA35: 1 | AB35: 4 | AC35: 9 | AD35: 4 | AE35: 37 | AF35: 8 | AG35: 1 | AH35: 0 | AI35: 0 | AJ35: 0 | AK35: =P35+S35+V35+Y35+AB35+AE35+AH35 -> 41 | AL35: =Q35+T35+W35+Z35+AC35+AF35+AI35 -> 199 | AM35: =AK35+AL35 -> 240 | AN35: =R35+U35+X35+AA35+AD35+AG35+AJ35 -> 23 | AO35: =O35/H35*100 -> 23.529412 | AP35: =AN35/H35*100 -> 33.823529 | AQ35: =AN35/AM35*100 -> 9.5833333 | AR35: =AK35/AM35*100 -> 17.083333 | AS35: =AL35/AM35*100 -> 82.916667 | AT35: =R35/AN35*100 -> 0 | AU35: =U35/AN35*100 -> 47.826087 | AV35: =X35/AN35*100 -> 26.086957 | AW35: =AA35/AN35*100 -> 4.3478261 | AX35: =AD35/AN35*100 -> 17.391304 | AY35: =AG35/AN35*100 -> 4.3478261 | AZ35: =AJ35/AN35*100 -> 0
A36: C.S. Machareti | B36: Comunidad Tati | C36: 156 | D36: 45797 | E36: 45805 | F36: 45 | G36: 0 | H36: =F36+G36 -> 45 | I36: 0 | J36: 0 | K36: =H36+I36+J36 -> 45 | L36: 0 | M36: 0 | N36: 45 | O36: 9 | P36: 0 | Q36: 0 | R36: 0 | S36: 0 | T36: 76 | U36: 2 | V36: 0 | W36: 24 | X36: 1 | Y36: 1 | Z36: 12 | AA36: 6 | AB36: 0 | AC36: 0 | AD36: 0 | AE36: 0 | AF36: 9 | AG36: 5 | AH36: 0 | AI36: 0 | AJ36: 0 | AK36: =P36+S36+V36+Y36+AB36+AE36+AH36 -> 1 | AL36: =Q36+T36+W36+Z36+AC36+AF36+AI36 -> 121 | AM36: =AK36+AL36 -> 122 | AN36: =R36+U36+X36+AA36+AD36+AG36+AJ36 -> 14 | AO36: =O36/H36*100 -> 20 | AP36: =AN36/H36*100 -> 31.111111 | AQ36: =AN36/AM36*100 -> 11.47541 | AR36: =AK36/AM36*100 -> 0.81967213 | AS36: =AL36/AM36*100 -> 99.180328 | AT36: =R36/AN36*100 -> 0 | AU36: =U36/AN36*100 -> 14.285714 | AV36: =X36/AN36*100 -> 7.1428571 | AW36: =AA36/AN36*100 -> 42.857143 | AX36: =AD36/AN36*100 -> 0 | AY36: =AG36/AN36*100 -> 35.714286 | AZ36: =AJ36/AN36*100 -> 0
A37: Total Mayo | B37: 2 | C37: =SUM(C33:C36)+C30 -> 2988 | D37: =MIN(D35:D36) -> 45797 | E37: =MAX(E35:E36) -> 45805 | F37: =SUM(F35:F36) -> 113 | G37: =SUM(G35:G36) -> 0 | H37: =SUM(H35:H36) -> 113 | I37: =SUM(I35:I36) -> 0 | J37: =SUM(J35:J36) -> 0 | K37: =SUM(K35:K36) -> 113 | L37: =SUM(L35:L36) -> 0 | M37: =SUM(M35:M36) -> 0 | ... AJ37: =SUM(AJ35:AJ36) -> 0 | AK37: =P37+S37+V37+Y37+AB37+AE37+AH37 -> 42 | AL37: =Q37+T37+W37+Z37+AC37+AF37+AI37 -> 320 | AM37: =AK37+AL37 -> 362 | AN37: =R37+U37+X37+AA37+AD37+AG37+AJ37 -> 37 | AO37: =O37/H37*100 -> 22.123894 | AP37: =AN37/H37*100 -> 32.743363 | AQ37: =AN37/AM37*100 -> 10.220994 | AR37: =AK37/AM37*100 -> 11.60221 | AS37: =AL37/AM37*100 -> 88.39779 | AT37: =R37/AN37*100 -> 0 | AU37: =U37/AN37*100 -> 35.135135 | AV37: =X37/AN37*100 -> 18.918919 | AW37: =AA37/AN37*100 -> 18.918919 | AX37: =AD37/AN37*100 -> 10.810811 | AY37: =AG37/AN37*100 -> 16.216216 | AZ37: =AJ37/AN37*100 -> 0
A38: C.S. Machareti | B38: Machareti | C38: =SUM(C39:C40) -> 548 | D38: =MIN(D39:D40) -> 45811 | E38: =MAX(E39:E40) -> 45834 | F38: =SUM(F39:F40) -> 173 | G38: =SUM(G39:G40) -> 0 | H38: =SUM(H39:H40) -> 173 | I38: =SUM(I39:I40) -> 18 | J38: =SUM(J39:J40) -> 0 | K38: =SUM(K39:K40) -> 191 | L38: =SUM(L39:L40) -> 18 | M38: =SUM(M39:M40) -> 0 | ... AJ38: =SUM(AJ39:AJ40) -> 0 | AK38: =P38+S38+V38+Y38+AB38+AE38+AH38 -> 9 | AL38: =Q38+T38+W38+Z38+AC38+AF38+AI38 -> 298 | AM38: =AK38+AL38 -> 307 | AN38: =R38+U38+X38+AA38+AD38+AG38+AJ38 -> 21 | AO38: =O38/H38*100 -> 10.404624 | AP38: =AN38/H38*100 -> 12.138728 | AQ38: =AN38/AM38*100 -> 6.8403909 | AR38: =AK38/AM38*100 -> 2.9315961 | AS38: =AL38/AM38*100 -> 97.068404 | AT38: =R38/AN38*100 -> 0 | AU38: =U38/AN38*100 -> 42.857143 | AV38: =X38/AN38*100 -> 33.333333 | AW38: =AA38/AN38*100 -> 4.7619048 | AX38: =AD38/AN38*100 -> 14.285714 | AY38: =AG38/AN38*100 -> 4.7619048 | AZ38: =AJ38/AN38*100 -> 0
B39: Barrio San Jose | C39: 503 | D39: 45811 | E39: 45834 | F39: 161 | G39: 0 | H39: =F39+G39 -> 161 | I39: 18 | J39: 0 | K39: =H39+I39+J39 -> 179 | L39: 18 | M39: 0 | N39: 0 | O39: 16 | P39: 0 | Q39: 0 | R39: 0 | S39: 0 | T39: 237 | U39: 8 | V39: 0 | W39: 29 | X39: 7 | Y39: 0 | Z39: 1 | AA39: 0 | AB39: 4 | AC39: 5 | AD39: 3 | AE39: 5 | AF39: 1 | AG39: 1 | AH39: 0 | AI39: 0 | AJ39: 0 | AK39: =P39+S39+V39+Y39+AB39+AE39+AH39 -> 9 | AL39: =Q39+T39+W39+Z39+AC39+AF39+AI39 -> 273 | AM39: =AK39+AL39 -> 282 | AN39: =R39+U39+X39+AA39+AD39+AG39+AJ39 -> 19 | AO39: =O39/H39*100 -> 9.9378882 | AP39: =AN39/H39*100 -> 11.801242 | AQ39: =AN39/AM39*100 -> 6.7375887 | AR39: =AK39/AM39*100 -> 3.1914894 | AS39: =AL39/AM39*100 -> 96.808511 | AT39: =R39/AN39*100 -> 0 | AU39: =U39/AN39*100 -> 42.105263 | AV39: =X39/AN39*100 -> 36.842105 | AW39: =AA39/AN39*100 -> 0 | AX39: =AD39/AN39*100 -> 15.789474 | AY39: =AG39/AN39*100 -> 5.2631579 | AZ39: =AJ39/AN39*100 -> 0
B40: Barrio Virgen del Carmen | C40: 45 | D40: 45819 | E40: 45819 | F40: 12 | G40: 0 | H40: =F40+G40 -> 12 | I40: 0 | J40: 0 | K40: =H40+I40+J40 -> 12 | L40: 0 | M40: 0 | N40: 0 | O40: 2 | P40: 0 | Q40: 0 | R40: 0 | S40: 0 | T40: 16 | U40: 1 | V40: 0 | W40: 0 | X40: 0 | Y40: 0 | Z40: 9 | AA40: 1 | AB40: 0 | AC40: 0 | AD40: 0 | AE40: 0 | AF40: 0 | AG40: 0 | AH40: 0 | AI40: 0 | AJ40: 0 | AK40: =P40+S40+V40+Y40+AB40+AE40+AH40 -> 0 | AL40: =Q40+T40+W40+Z40+AC40+AF40+AI40 -> 25 | AM40: =AK40+AL40 -> 25 | AN40: =R40+U40+X40+AA40+AD40+AG40+AJ40 -> 2 | AO40: =O40/H40*100 -> 16.666667 | AP40: =AN40/H40*100 -> 16.666667 | AQ40: =AN40/AM40*100 -> 8 | AR40: =AK40/AM40*100 -> 0 | AS40: =AL40/AM40*100 -> 100 | AT40: =R40/AN40*100 -> 0 | AU40: =U40/AN40*100 -> 50 | AV40: =X40/AN40*100 -> 0 | AW40: =AA40/AN40*100 -> 50 | AX40: =AD40/AN40*100 -> 0 | AY40: =AG40/AN40*100 -> 0 | AZ40: =AJ40/AN40*100 -> 0
A41: Total Junio | B41: 2 | C41: =C38 -> 548 | D41: =MIN(D38:D40) -> 45811 | E41: =MAX(E38:E40) -> 45834 | F41: =F38 -> 173 | G41: =G38 -> 0 | H41: =H38 -> 173 | I41: =I38 -> 18 | J41: =J38 -> 0 | K41: =K38 -> 191 | L41: =L38 -> 18 | M41: =M38 -> 0 | ... AJ41: =AJ38 -> 0 | AK41: =P41+S41+V41+Y41+AB41+AE41+AH41 -> 9 | AL41: =Q41+T41+W41+Z41+AC41+AF41+AI41 -> 298 | AM41: =AK41+AL41 -> 307 | AN41: =R41+U41+X41+AA41+AD41+AG41+AJ41 -> 21 | AO41: =O41/H41*100 -> 10.404624 | AP41: =AN41/H41*100 -> 12.138728 | AQ41: =AN41/AM41*100 -> 6.8403909 | AR41: =AK41/AM41*100 -> 2.9315961 | AS41: =AL41/AM41*100 -> 97.068404 | AT41: =R41/AN41*100 -> 0 | AU41: =U41/AN41*100 -> 42.857143 | AV41: =X41/AN41*100 -> 33.333333 | AW41: =AA41/AN41*100 -> 4.7619048 | AX41: =AD41/AN41*100 -> 14.285714 | AY41: =AG41/AN41*100 -> 4.7619048 | AZ41: =AJ41/AN41*100 -> 0
...

Sheet Monteagudo
A1: ENCUESTA DE LARVARIA DE AEDES AEGYPTI POR COMUNIDAD - BARRIOS DE MONTEAGUDO GESTION 2025
A3: Establecimiento | B3: Barrio / Comunidad | C3: Habitantaes protegidos | D3: FECHA | F3: PREDIOS | K3: TOTAL PREDIOS | L3: Manzanos | N3: VIVIENDAS | P3: Grupo A Depositos de Almacenamiento de Gran Volumen | V3: Grupo B Depositos de Transporte de Agua Moviles | Y3: Grupo C Depositos Fijos de Almacenamiento de Agua | AB3: Grupo D Depositos para Eliminacion | AH3: Grupo E Depositos Naturales | AK3: TOTAL | AO3: indicadores | AT3: INDICADORES DE ENTOMOLOGICOS - TIPO RECIPIENTE
D4: Inicio | E4: Final | F4: INSPECCIONADAS | H4: TOTAL | I4: Cerradas | J4: Renuentes | L4: EVALUADAS | M4: FOCO AEDES | N4: CON FOCO | O4: FOCO AEDES | P4: A1 | S4: A2 | V4: B | Y4: C | AB4: D1 | AE4: D2 | AH4: E | AK4: Total Recipinetes Secos | AL4: Total Recipinetes Agua | AM4: Total Recipinetes | AN4: Total Recipinetes Positivos (+) | AO4: Entomologico | AR4: Recipiente | AT4: Indice por tipo de recipiente A1 | AU4: Indice por tipo de recipiente A2 | AV4: Indice por tipo de recipiente B | AW4: Indice por tipo de recipiente C | AX4: Indice por tipo de recipiente D1 | AY4: Indice por tipo de recipiente D2 | AZ4: Indice por tipo de recipiente E
F5: Vivienda | G5: Otro | P5: S | Q5: A | R5: POSITIVOS (+) | S5: S | T5: A | U5: POSITIVOS (+) | V5: S | W5: A | X5: POSITIVOS (+) | Y5: S | Z5: A | AA5: POSITIVOS (+) | AB5: S | AC5: A | AD5: POSITIVOS (+) | AE5: S | AF5: A | AG5: POSITIVOS (+) | AH5: S | AI5: A | AJ5: POSITIVOS (+) | AO5: % Indice de Infestacion | AP5: % Indice Bretau | AQ5: % Indice Recipiente | AR5: % Recipientes Secos | AS5: % Recipientes con Agua
A6: Hosp. Monteagudo | B6: Monteagudo | C6: =SUM(C7:C12) -> 1077 | D6: =MIN(D7:D12) -> 45659 | E6: =MAX(E7:E12) -> 45687 | F6: =SUM(F7:F12) -> 300 | G6: =SUM(G7:G12) -> 0 | H6: =SUM(H7:H12) -> 300 | I6: =SUM(I7:I12) -> 0 | J6: =SUM(J7:J12) -> 0 | K6: =SUM(K7:K12) -> 300 | L6: =SUM(L7:L12) -> 0 | M6: =SUM(M7:M12) -> 0 | ... AJ6: =SUM(AJ7:AJ12) -> 0 | AK6: =P6+S6+V6+Y6+AB6+AE6+AH6 -> 14 | AL6: =Q6+T6+W6+Z6+AC6+AF6+AI6 -> 328 | AM6: =AK6+AL6 -> 342 | AN6: =R6+U6+X6+AA6+AD6+AG6+AJ6 -> 33 | AO6: =O6/H6*100 -> 9.3333333 | AP6: =AN6/H6*100 -> 11 | AQ6: =AN6/AM6*100 -> 9.6491228 | AR6: =AK6/AM6*100 -> 4.0935673 | AS6: =AL6/AM6*100 -> 95.906433 | AT6: =R6/AN6*100 -> 0 | AU6: =U6/AN6*100 -> 15.151515 | AV6: =X6/AN6*100 -> 45.454545 | AW6: =AA6/AN6*100 -> 3.030303 | AX6: =AD6/AN6*100 -> 30.30303 | AY6: =AG6/AN6*100 -> 6.0606061 | AZ6: =AJ6/AN6*100 -> 0
B7: Barrio Concepcion | C7: 73 | D7: 45659 | E7: 45659 | F7: 20 | G7: 0 | H7: =F7+G7 -> 20 | I7: 0 | J7: 0 | K7: =H7+I7+J7 -> 20 | L7: 0 | M7: 0 | N7: 0 | O7: 0 | P7: 0 | Q7: 0 | R7: 0 | S7: 0 | T7: 0 | U7: 0 | V7: 0 | W7: 0 | X7: 0 | Y7: 0 | Z7: 0 | AA7: 0 | AB7: 0 | AC7: 1 | AD7: 0 | AE7: 2 | AF7: 41 | AG7: 0 | AH7: 0 | AI7: 0 | AJ7: 0 | AK7: =P7+S7+V7+Y7+AB7+AE7+AH7 -> 2 | AL7: =Q7+T7+W7+Z7+AC7+AF7+AI7 -> 42 | AM7: =AK7+AL7 -> 44 | AN7: =R7+U7+X7+AA7+AD7+AG7+AJ7 -> 0 | AO7: =O7/H7*100 -> 0 | AP7: =AN7/H7*100 -> 0 | AQ7: =AN7/AM7*100 -> 0 | AR7: =AK7/AM7*100 -> 4.5454545 | AS7: =AL7/AM7*100 -> 95.454545 | AT7: =R7/AN7*100 -> #DIV/0! | AU7: =U7/AN7*100 -> #DIV/0! | AV7: =X7/AN7*100 -> #DIV/0! | AW7: =AA7/AN7*100 -> #DIV/0! | AX7: =AD7/AN7*100 -> #DIV/0! | AY7: =AG7/AN7*100 -> #DIV/0! | AZ7: =AJ7/AN7*100 -> #DIV/0!
B8: Barrio 1 de Mayo | C8: 166 | D8: 45666 | E8: 45666 | F8: 40 | G8: 0 | H8: =F8+G8 -> 40 | I8: 0 | J8: 0 | K8: =H8+I8+J8 -> 40 | L8: 0 | M8: 0 | N8: 0 | O8: 4 | P8: 0 | Q8: 0 | R8: 0 | S8: 0 | T8: 1 | U8: 1 | V8: 1 | W8: 10 | X8: 1 | Y8: 0 | Z8: 1 | AA8: 1 | AB8: 0 | AC8: 3 | AD8: 1 | AE8: 0 | AF8: 5 | AG8: 0 | AH8: 0 | AI8: 0 | AJ8: 0 | AK8: =P8+S8+V8+Y8+AB8+AE8+AH8 -> 1 | AL8: =Q8+T8+W8+Z8+AC8+AF8+AI8 -> 20 | AM8: =AK8+AL8 -> 21 | AN8: =R8+U8+X8+AA8+AD8+AG8+AJ8 -> 4 | AO8: =O8/H8*100 -> 10 | AP8: =AN8/H8*100 -> 10 | AQ8: =AN8/AM8*100 -> 19.047619 | AR8: =AK8/AM8*100 -> 4.7619048 | AS8: =AL8/AM8*100 -> 95.238095 | AT8: =R8/AN8*100 -> 0 | AU8: =U8/AN8*100 -> 25 | AV8: =X8/AN8*100 -> 25 | AW8: =AA8/AN8*100 -> 25 | AX8: =AD8/AN8*100 -> 25 | AY8: =AG8/AN8*100 -> 0 | AZ8: =AJ8/AN8*100 -> 0
B9: Barrio La Hoyada | C9: 71 | D9: 45671 | E9: 45671 | F9: 20 | G9: 0 | H9: =F9+G9 -> 20 | I9: 0 | J9: 0 | K9: =H9+I9+J9 -> 20 | L9: 0 | M9: 0 | N9: 0 | O9: 0 | P9: 0 | Q9: 0 | R9: 0 | S9: 0 | T9: 0 | U9: 0 | V9: 0 | W9: 6 | X9: 0 | Y9: 0 | Z9: 3 | AA9: 0 | AB9: 0 | AC9: 12 | AD9: 0 | AE9: 0 | AF9: 0 | AG9: 0 | AH9: 0 | AI9: 0 | AJ9: 0 | AK9: =P9+S9+V9+Y9+AB9+AE9+AH9 -> 0 | AL9: =Q9+T9+W9+Z9+AC9+AF9+AI9 -> 21 | AM9: =AK9+AL9 -> 21 | AN9: =R9+U9+X9+AA9+AD9+AG9+AJ9 -> 0 | AO9: =O9/H9*100 -> 0 | AP9: =AN9/H9*100 -> 0 | AQ9: =AN9/AM9*100 -> 0 | AR9: =AK9/AM9*100 -> 0 | AS9: =AL9/AM9*100 -> 100 | AT9: =R9/AN9*100 -> #DIV/0! | AU9: =U9/AN9*100 -> #DIV/0! | AV9: =X9/AN9*100 -> #DIV/0! | AW9: =AA9/AN9*100 -> #DIV/0! | AX9: =AD9/AN9*100 -> #DIV/0! | AY9: =AG9/AN9*100 -> #DIV/0! | AZ9: =AJ9/AN9*100 -> #DIV/0!
B10: Barrio Sinay | C10: 144 | D10: 45671 | E10: 45671 | F10: 40 | G10: 0 | H10: =F10+G10 -> 40 | I10: 0 | J10: 0 | K10: =H10+I10+J10 -> 40 | L10: 0 | M10: 0 | N10: 0 | O10: 9 | P10: 0 | Q10: 0 | R10: 0 | S10: 0 | T10: 1 | U10: 3 | V10: 1 | W10: 26 | X10: 5 | Y10: 0 | Z10: 0 | AA10: 0 | AB10: 2 | AC10: 12 | AD10: 2 | AE10: 0 | AF10: 6 | AG10: 1 | AH10: 0 | AI10: 0 | AJ10: 0 | AK10: =P10+S10+V10+Y10+AB10+AE10+AH10 -> 3 | AL10: =Q10+T10+W10+Z10+AC10+AF10+AI10 -> 45 | AM10: =AK10+AL10 -> 48 | AN10: =R10+U10+X10+AA10+AD10+AG10+AJ10 -> 11 | AO10: =O10/H10*100 -> 22.5 | AP10: =AN10/H10*100 -> 27.5 | AQ10: =AN10/AM10*100 -> 22.916667 | AR10: =AK10/AM10*100 -> 6.25 | AS10: =AL10/AM10*100 -> 93.75 | AT10: =R10/AN10*100 -> 0 | AU10: =U10/AN10*100 -> 27.272727 | AV10: =X10/AN10*100 -> 45.454545 | AW10: =AA10/AN10*100 -> 0 | AX10: =AD10/AN10*100 -> 18.181818 | AY10: =AG10/AN10*100 -> 9.0909091 | AZ10: =AJ10/AN10*100 -> 0
B11: Barrio El Paraiso | C11: 277 | D11: 45672 | E11: 45673 | F11: 80 | G11: 0 | H11: =F11+G11 -> 80 | I11: 0 | J11: 0 | K11: =H11+I11+J11 -> 80 | L11: 0 | M11: 0 | N11: 0 | O11: 8 | P11: 0 | Q11: 1 | R11: 0 | S11: 0 | T11: 3 | U11: 0 | V11: 3 | W11: 38 | X11: 8 | Y11: 0 | Z11: 5 | AA11: 0 | AB11: 0 | AC11: 16 | AD11: 2 | AE11: 0 | AF11: 3 | AG11: 1 | AH11: 0 | AI11: 0 | AJ11: 0 | AK11: =P11+S11+V11+Y11+AB11+AE11+AH11 -> 3 | AL11: =Q11+T11+W11+Z11+AC11+AF11+AI11 -> 66 | AM11: =AK11+AL11 -> 69 | AN11: =R11+U11+X11+AA11+AD11+AG11+AJ11 -> 11 | AO11: =O11/H11*100 -> 10 | AP11: =AN11/H11*100 -> 13.75 | AQ11: =AN11/AM11*100 -> 15.942029 | AR11: =AK11/AM11*100 -> 4.3478261 | AS11: =AL11/AM11*100 -> 95.652174 | AT11: =R11/AN11*100 -> 0 | AU11: =U11/AN11*100 -> 0 | AV11: =X11/AN11*100 -> 72.727273 | AW11: =AA11/AN11*100 -> 0 | AX11: =AD11/AN11*100 -> 18.181818 | AY11: =AG11/AN11*100 -> 9.0909091 | AZ11: =AJ11/AN11*100 -> 0
B12: Barrio La Tablada | C12: 346 | D12: 45684 | E12: 45687 | F12: 100 | G12: 0 | H12: =F12+G12 -> 100 | I12: 0 | J12: 0 | K12: =H12+I12+J12 -> 100 | L12: 0 | M12: 0 | N12: 0 | O12: 7 | P12: 0 | Q12: 0 | R12: 0 | S12: 0 | T12: 1 | U12: 1 | V12: 0 | W12: 7 | X12: 1 | Y12: 0 | Z12: 17 | AA12: 0 | AB12: 0 | AC12: 22 | AD12: 5 | AE12: 5 | AF12: 87 | AG12: 0 | AH12: 0 | AI12: 0 | AJ12: 0 | AK12: =P12+S12+V12+Y12+AB12+AE12+AH12 -> 5 | AL12: =Q12+T12+W12+Z12+AC12+AF12+AI12 -> 134 | AM12: =AK12+AL12 -> 139 | AN12: =R12+U12+X12+AA12+AD12+AG12+AJ12 -> 7 | AO12: =O12/H12*100 -> 7 | AP12: =AN12/H12*100 -> 7 | AQ12: =AN12/AM12*100 -> 5.0359712 | AR12: =AK12/AM12*100 -> 3.5971223 | AS12: =AL12/AM12*100 -> 96.402878 | AT12: =R12/AN12*100 -> 0 | AU12: =U12/AN12*100 -> 14.285714 | AV12: =X12/AN12*100 -> 14.285714 | AW12: =AA12/AN12*100 -> 0 | AX12: =AD12/AN12*100 -> 71.428571 | AY12: =AG12/AN12*100 -> 0 | AZ12: =AJ12/AN12*100 -> 0
A13: C.S. Candua | B13: Candua | C13: =SUM(C14:C17) -> 1161 | D13: =SUM(D14:D17) -> 182686 | E13: =MAX(E14:E17) -> 45684 | F13: =SUM(F14:F17) -> 319 | G13: =SUM(G14:G17) -> 1 | H13: =SUM(H14:H17) -> 320 | I13: =SUM(I14:I17) -> 0 | J13: =SUM(J14:J17) -> 0 | K13: =SUM(K14:K17) -> 320 | L13: =SUM(L14:L17) -> 0 | M13: =SUM(M14:M17) -> 0 | ... AJ13: =SUM(AJ14:AJ17) -> 0 | AK13: =P13+S13+V13+Y13+AB13+AE13+AH13 -> 23 | AL13: =Q13+T13+W13+Z13+AC13+AF13+AI13 -> 500 | AM13: =AK13+AL13 -> 523 | AN13: =R13+U13+X13+AA13+AD13+AG13+AJ13 -> 38 | AO13: =O13/H13*100 -> 6.5625 | AP13: =AN13/H13*100 -> 11.875 | AQ13: =AN13/AM13*100 -> 7.2657744 | AR13: =AK13/AM13*100 -> 4.3977055 | AS13: =AL13/AM13*100 -> 95.602294 | AT13: =R13/AN13*100 -> 0 | AU13: =U13/AN13*100 -> 0 | AV13: =X13/AN13*100 -> 0 | AW13: =AA13/AN13*100 -> 2.6315789 | AX13: =AD13/AN13*100 -> 89.473684 | AY13: =AG13/AN13*100 -> 7.8947368 | AZ13: =AJ13/AN13*100 -> 0
B14: Barrio Jose Barbero | C14: 506 | D14: 45660 | E14: 45670 | F14: 140 | G14: 0 | H14: =F14+G14 -> 140 | I14: 0 | J14: 0 | K14: =H14+I14+J14 -> 140 | L14: 0 | M14: 0 | N14: 0 | O14: 9 | P14: 0 | Q14: 0 | R14: 0 | S14: 0 | T14: 8 | U14: 0 | V14: 0 | W14: 0 | X14: 0 | Y14: 0 | Z14: 2 | AA14: 0 | AB14: 1 | AC14: 42 | AD14: 15 | AE14: 22 | AF14: 196 | AG14: 0 | AH14: 0 | AI14: 0 | AJ14: 0 | AK14: =P14+S14+V14+Y14+AB14+AE14+AH14 -> 23 | AL14: =Q14+T14+W14+Z14+AC14+AF14+AI14 -> 248 | AM14: =AK14+AL14 -> 271 | AN14: =R14+U14+X14+AA14+AD14+AG14+AJ14 -> 15 | AO14: =O14/H14*100 -> 6.4285714 | AP14: =AN14/H14*100 -> 10.714286 | AQ14: =AN14/AM14*100 -> 5.5350554 | AR14: =AK14/AM14*100 -> 8.4870849 | AS14: =AL14/AM14*100 -> 91.512915 | AT14: =R14/AN14*100 -> 0 | AU14: =U14/AN14*100 -> 0 | AV14: =X14/AN14*100 -> 0 | AW14: =AA14/AN14*100 -> 0 | AX14: =AD14/AN14*100 -> 100 | AY14: =AG14/AN14*100 -> 0 | AZ14: =AJ14/AN14*100 -> 0
B15: Barrio 21 de Septiembre | C15: 221 | D15: 45671 | E15: 45673 | F15: 60 | G15: 0 | H15: 60 | I15: 0 | J15: 0 | K15: =H15+I15+J15 -> 60 | L15: 0 | M15: 0 | N15: 0 | O15: 6 | P15: 0 | Q15: 0 | R15: 0 | S15: 0 | T15: 5 | U15: 0 | V15: 0 | W15: 0 | X15: 0 | Y15: 0 | Z15: 2 | AA15: 1 | AB15: 0 | AC15: 13 | AD15: 6 | AE15: 0 | AF15: 66 | AG15: 3 | AH15: 0 | AI15: 0 | AJ15: 0 | AK15: =P15+S15+V15+Y15+AB15+AE15+AH15 -> 0 | AL15: =Q15+T15+W15+Z15+AC15+AF15+AI15 -> 86 | AM15: =AK15+AL15 -> 86 | AN15: =R15+U15+X15+AA15+AD15+AG15+AJ15 -> 10 | AO15: =O15/H15*100 -> 10 | AP15: =AN15/H15*100 -> 16.666667 | AQ15: =AN15/AM15*100 -> 11.627907 | AR15: =AK15/AM15*100 -> 0 | AS15: =AL15/AM15*100 -> 100 | AT15: =R15/AN15*100 -> 0 | AU15: =U15/AN15*100 -> 0 | AV15: =X15/AN15*100 -> 0 | AW15: =AA15/AN15*100 -> 10 | AX15: =AD15/AN15*100 -> 60 | AY15: =AG15/AN15*100 -> 30 | AZ15: =AJ15/AN15*100 -> 0
B16: Barrio 24 de Mayo | C16: 297 | D16: 45674 | E16: 45680 | F16: 80 | G16: 0 | H16: =F16+G16 -> 80 | I16: 0 | J16: 0 | K16: =H16+I16+J16 -> 80 | L16: 0 | M16: 0 | N16: 0 | O16: 4 | P16: 0 | Q16: 0 | R16: 0 | S16: 0 | T16: 5 | U16: 0 | V16: 0 | W16: 0 | X16: 0 | Y16: 0 | Z16: 1 | AA16: 0 | AB16: 0 | AC16: 17 | AD16: 10 | AE16: 0 | AF16: 90 | AG16: 0 | AH16: 0 | AI16: 0 | AJ16: 0 | AK16: =P16+S16+V16+Y16+AB16+AE16+AH16 -> 0 | AL16: =Q16+T16+W16+Z16+AC16+AF16+AI16 -> 113 | AM16: =AK16+AL16 -> 113 | AN16: =R16+U16+X16+AA16+AD16+AG16+AJ16 -> 10 | AO16: =O16/H16*100 -> 5 | AP16: =AN16/H16*100 -> 12.5 | AQ16: =AN16/AM16*100 -> 8.8495575 | AR16: =AK16/AM16*100 -> 0 | AS16: =AL16/AM16*100 -> 100 | AT16: =R16/AN16*100 -> 0 | AU16: =U16/AN16*100 -> 0 | AV16: =X16/AN16*100 -> 0 | AW16: =AA16/AN16*100 -> 0 | AX16: =AD16/AN16*100 -> 100 | AY16: =AG16/AN16*100 -> 0 | AZ16: =AJ16/AN16*100 -> 0
B17: Barrio San Juan | C17: 137 | D17: 45681 | E17: 45684 | F17: 39 | G17: 1 | H17: =F17+G17 -> 40 | I17: 0 | J17: 0 | K17: =H17+I17+J17 -> 40 | L17: 0 | M17: 0 | N17: 0 | O17: 2 | P17: 0 | Q17: 0 | R17: 0 | S17: 0 | T17: 4 | U17: 0 | V17: 0 | W17: 0 | X17: 0 | Y17: 0 | Z17: 0 | AA17: 0 | AB17: 0 | AC17: 4 | AD17: 3 | AE17: 0 | AF17: 45 | AG17: 0 | AH17: 0 | AI17: 0 | AJ17: 0 | AK17: =P17+S17+V17+Y17+AB17+AE17+AH17 -> 0 | AL17: =Q17+T17+W17+Z17+AC17+AF17+AI17 -> 53 | AM17: =AK17+AL17 -> 53 | AN17: =R17+U17+X17+AA17+AD17+AG17+AJ17 -> 3 | AO17: =O17/H17*100 -> 5 | AP17: =AN17/H17*100 -> 7.5 | AQ17: =AN17/AM17*100 -> 5.6603774 | AR17: =AK17/AM17*100 -> 0 | AS17: =AL17/AM17*100 -> 100 | AT17: =R17/AN17*100 -> 0 | AU17: =U17/AN17*100 -> 0 | AV17: =X17/AN17*100 -> 0 | AW17: =AA17/AN17*100 -> 0 | AX17: =AD17/AN17*100 -> 100 | AY17: =AG17/AN17*100 -> 0 | AZ17: =AJ17/AN17*100 -> 0
A18: Total Enero | B18: 10 | C18: =C6+C13 -> 2238 | D18: =MIN(D7:D17) -> 45659 | E18: =MAX(E7:E17) -> 45687 | F18: =F6+F13 -> 619 | G18: =G6+G13 -> 1 | H18: =H6+H13 -> 620 | I18: =I6+I13 -> 0 | J18: =J6+J13 -> 0 | K18: =K6+K13 -> 620 | L18: =L6+L13 -> 0 | M18: =M6+M13 -> 0 | ... AJ18: =AJ6+AJ13 -> 0 | AK18: =P18+S18+V18+Y18+AB18+AE18+AH18 -> 37 | AL18: =Q18+T18+W18+Z18+AC18+AF18+AI18 -> 828 | AM18: =AK18+AL18 -> 865 | AN18: =R18+U18+X18+AA18+AD18+AG18+AJ18 -> 71 | AO18: =O18/H18*100 -> 7.9032258 | AP18: =AN18/H18*100 -> 11.451613 | AQ18: =AN18/AM18*100 -> 8.2080925 | AR18: =AK18/AM18*100 -> 4.2774566 | AS18: =AL18/AM18*100 -> 95.722543 | AT18: =R18/AN18*100 -> 0 | AU18: =U18/AN18*100 -> 7.0422535 | AV18: =X18/AN18*100 -> 21.126761 | AW18: =AA18/AN18*100 -> 2.8169014 | AX18: =AD18/AN18*100 -> 61.971831 | AY18: =AG18/AN18*100 -> 7.0422535 | AZ18: =AJ18/AN18*100 -> 0
A19: Hosp. Monteagudo | B19: Monteagudo | C19: =SUM(C20:C24) -> 662 | D19: =MIN(D20:D24) -> 45693 | E19: =MAX(E20:E24) -> 45701 | F19: =SUM(F20:F24) -> 173 | G19: =SUM(G20:G24) -> 0 | H19: =SUM(H20:H24) -> 173 | I19: =SUM(I20:I24) -> 6 | J19: =SUM(J20:J24) -> 0 | K19: =SUM(K20:K24) -> 179 | L19: =SUM(L20:L24) -> 0 | M19: =SUM(M20:M24) -> 0 | ... AJ19: =SUM(AJ20:AJ24) -> 0 | AK19: =P19+S19+V19+Y19+AB19+AE19+AH19 -> 80 | AL19: =Q19+T19+W19+Z19+AC19+AF19+AI19 -> 178 | AM19: =AK19+AL19 -> 258 | AN19: =R19+U19+X19+AA19+AD19+AG19+AJ19 -> 47 | AO19: =O19/H19*100 -> 17.919075 | AP19: =AN19/H19*100 -> 27.16763 | AQ19: =AN19/AM19*100 -> 18.217054 | AR19: =AK19/AM19*100 -> 31.007752 | AS19: =AL19/AM19*100 -> 68.992248 | AT19: =R19/AN19*100 -> 0 | AU19: =U19/AN19*100 -> 6.3829787 | AV19: =X19/AN19*100 -> 19.148936 | AW19: =AA19/AN19*100 -> 4.2553191 | AX19: =AD19/AN19*100 -> 63.829787 | AY19: =AG19/AN19*100 -> 6.3829787 | AZ19: =AJ19/AN19*100 -> 0
B20: Barrio Los Pinos | C20: 92 | D20: 04/02025 | E20: 45699 | F20: 24 | G20: 0 | H20: =F20+G20 -> 24 | I20: 0 | J20: 0 | K20: =H20+I20+J20 -> 24 | L20: 0 | M20: 0 | N20: 0 | O20: 8 | P20: 0 | Q20: 0 | R20: 0 | S20: 0 | T20: 3 | U20: 2 | V20: 0 | W20: 14 | X20: 3 | Y20: 0 | Z20: 2 | AA20: 0 | AB20: 3 | AC20: 18 | AD20: 14 | AE20: 0 | AF20: 12 | AG20: 1 | AH20: 0 | AI20: 0 | AJ20: 0 | AK20: =P20+S20+V20+Y20+AB20+AE20+AH20 -> 3 | AL20: =Q20+T20+W20+Z20+AC20+AF20+AI20 -> 49 | AM20: =AK20+AL20 -> 52 | AN20: =R20+U20+X20+AA20+AD20+AG20+AJ20 -> 20 | AO20: =O20/H20*100 -> 33.333333 | AP20: =AN20/H20*100 -> 83.333333 | AQ20: =AN20/AM20*100 -> 38.461538 | AR20: =AK20/AM20*100 -> 5.7692308 | AS20: =AL20/AM20*100 -> 94.230769 | AT20: =R20/AN20*100 -> 0 | AU20: =U20/AN20*100 -> 10 | AV20: =X20/AN20*100 -> 15 | AW20: =AA20/AN20*100 -> 0 | AX20: =AD20/AN20*100 -> 70 | AY20: =AG20/AN20*100 -> 5 | AZ20: =AJ20/AN20*100 -> 0
B21: Barrio Lagunillitas | C21: 172 | D21: 45693 | E21: 45699 | F21: 41 | G21: 0 | H21: =F21+G21 -> 41 | I21: 0 | J21: 0 | K21: =H21+I21+J21 -> 41 | L21: 0 | M21: 0 | N21: 0 | O21: 7 | P21: 0 | Q21: 0 | R21: 0 | S21: 0 | T21: 6 | U21: 0 | V21: 2 | W21: 9 | X21: 2 | Y21: 0 | Z21: 0 | AA21: 0 | AB21: 0 | AC21: 13 | AD21: 6 | AE21: 23 | AF21: 9 | AG21: 1 | AH21: 0 | AI21: 0 | AJ21: 0 | AK21: =P21+S21+V21+Y21+AB21+AE21+AH21 -> 25 | AL21: =Q21+T21+W21+Z21+AC21+AF21+AI21 -> 37 | AM21: =AK21+AL21 -> 62 | AN21: =R21+U21+X21+AA21+AD21+AG21+AJ21 -> 9 | AO21: =O21/H21*100 -> 17.073171 | AP21: =AN21/H21*100 -> 21.95122 | AQ21: =AN21/AM21*100 -> 14.516129 | AR21: =AK21/AM21*100 -> 40.322581 | AS21: =AL21/AM21*100 -> 59.677419 | AT21: =R21/AN21*100 -> 0 | AU21: =U21/AN21*100 -> 0 | AV21: =X21/AN21*100 -> 22.222222 | AW21: =AA21/AN21*100 -> 0 | AX21: =AD21/AN21*100 -> 66.666667 | AY21: =AG21/AN21*100 -> 11.111111 | AZ21: =AJ21/AN21*100 -> 0
B22: Barrio La Tablada | C22: 40 | D22: 45699 | E22: 45699 | F22: 10 | G22: 0 | H22: =F22+G22 -> 10 | I22: 0 | J22: 0 | K22: =H22+I22+J22 -> 10 | L22: 0 | M22: 0 | N22: 0 | O22: 1 | P22: 0 | Q22: 0 | R22: 0 | S22: 0 | T22: 0 | U22: 0 | V22: 3 | W22: 3 | X22: 0 | Y22: 0 | Z22: 1 | AA22: 1 | AB22: 0 | AC22: 0 | AD22: 0 | AE22: 0 | AF22: 0 | AG22: 0 | AH22: 0 | AI22: 0 | AJ22: 0 | AK22: =P22+S22+V22+Y22+AB22+AE22+AH22 -> 3 | AL22: =Q22+T22+W22+Z22+AC22+AF22+AI22 -> 4 | AM22: =AK22+AL22 -> 7 | AN22: =R22+U22+X22+AA22+AD22+AG22+AJ22 -> 1 | AO22: =O22/H22*100 -> 10 | AP22: =AN22/H22*100 -> 10 | AQ22: =AN22/AM22*100 -> 14.285714 | AR22: =AK22/AM22*100 -> 42.857143 | AS22: =AL22/AM22*100 -> 57.142857 | AT22: =R22/AN22*100 -> 0 | AU22: =U22/AN22*100 -> 0 | AV22: =X22/AN22*100 -> 0 | AW22: =AA22/AN22*100 -> 100 | AX22: =AD22/AN22*100 -> 0 | AY22: =AG22/AN22*100 -> 0 | AZ22: =AJ22/AN22*100 -> 0
B23: Barrio San Jose | C23: 80 | D23: 45701 | E23: 45701 | F23: 18 | G23: 0 | H23: =F23+G23 -> 18 | I23: 0 | J23: 0 | K23: =H23+I23+J23 -> 18 | L23: 0 | M23: 0 | N23: 0 | O23: 4 | P23: 0 | Q23: 0 | R23: 0 | S23: 0 | T23: 1 | U23: 0 | V23: 0 | W23: 4 | X23: 2 | Y23: 0 | Z23: 2 | AA23: 0 | AB23: 0 | AC23: 3 | AD23: 2 | AE23: 0 | AF23: 8 | AG23: 0 | AH23: 0 | AI23: 0 | AJ23: 0 | AK23: =P23+S23+V23+Y23+AB23+AE23+AH23 -> 0 | AL23: =Q23+T23+W23+Z23+AC23+AF23+AI23 -> 18 | AM23: =AK23+AL23 -> 18 | AN23: =R23+U23+X23+AA23+AD23+AG23+AJ23 -> 4 | AO23: =O23/H23*100 -> 22.222222 | AP23: =AN23/H23*100 -> 22.222222 | AQ23: =AN23/AM23*100 -> 22.222222 | AR23: =AK23/AM23*100 -> 0 | AS23: =AL23/AM23*100 -> 100 | AT23: =R23/AN23*100 -> 0 | AU23: =U23/AN23*100 -> 0 | AV23: =X23/AN23*100 -> 50 | AW23: =AA23/AN23*100 -> 0 | AX23: =AD23/AN23*100 -> 50 | AY23: =AG23/AN23*100 -> 0 | AZ23: =AJ23/AN23*100 -> 0
B24: Barrio Sinay | C24: 278 | D24: 45693 | E24: 45693 | F24: 80 | G24: 0 | H24: =F24+G24 -> 80 | I24: 6 | J24: 0 | K24: =H24+I24+J24 -> 86 | L24: 0 | M24: 0 | N24: 0 | O24: 11 | P24: 3 | Q24: 1 | R24: 0 | S24: 3 | T24: 2 | U24: 1 | V24: 9 | W24: 21 | X24: 2 | Y24: 1 | Z24: 3 | AA24: 1 | AB24: 3 | AC24: 30 | AD24: 8 | AE24: 30 | AF24: 13 | AG24: 1 | AH24: 0 | AI24: 0 | AJ24: 0 | AK24: =P24+S24+V24+Y24+AB24+AE24+AH24 -> 49 | AL24: =Q24+T24+W24+Z24+AC24+AF24+AI24 -> 70 | AM24: =AK24+AL24 -> 119 | AN24: =R24+U24+X24+AA24+AD24+AG24+AJ24 -> 13 | AO24: =O24/H24*100 -> 13.75 | AP24: =AN24/H24*100 -> 16.25 | AQ24: =AN24/AM24*100 -> 10.92437 | AR24: =AK24/AM24*100 -> 41.176471 | AS24: =AL24/AM24*100 -> 58.823529 | AT24: =R24/AN24*100 -> 0 | AU24: =U24/AN24*100 -> 7.6923077 | AV24: =X24/AN24*100 -> 15.384615 | AW24: =AA24/AN24*100 -> 7.6923077 | AX24: =AD24/AN24*100 -> 61.538462 | AY24: =AG24/AN24*100 -> 7.6923077 | AZ24: =AJ24/AN24*100 -> 0
A25: C.S. Candua | B25: Candua | C25: =SUM(C26:C28) -> 565 | D25: =MIN(D26:D28) -> 45694 | E25: =MAX(E26:E28) -> 45705 | F25: =SUM(F26:F28) -> 180 | G25: =SUM(G26:G28) -> 0 | H25: =SUM(H26:H28) -> 180 | I25: =SUM(I26:I28) -> 0 | J25: =SUM(J26:J28) -> 0 | K25: =SUM(K26:K28) -> 180 | L25: =SUM(L26:L28) -> 0 | M25: =SUM(M26:M28) -> 0 | ... AJ25: =SUM(AJ26:AJ28) -> 0 | AK25: =P25+S25+V25+Y25+AB25+AE25+AH25 -> 26 | AL25: =Q25+T25+W25+Z25+AC25+AF25+AI25 -> 183 | AM25: =AK25+AL25 -> 209 | AN25: =R25+U25+X25+AA25+AD25+AG25+AJ25 -> 36 | AO25: =O25/H25*100 -> 11.666667 | AP25: =AN25/H25*100 -> 20 | AQ25: =AN25/AM25*100 -> 17.22488 | AR25: =AK25/AM25*100 -> 12.440191 | AS25: =AL25/AM25*100 -> 87.559809 | AT25: =R25/AN25*100 -> 0 | AU25: =U25/AN25*100 -> 2.7777778 | AV25: =X25/AN25*100 -> 25 | AW25: =AA25/AN25*100 -> 5.5555556 | AX25: =AD25/AN25*100 -> 63.888889 | AY25: =AG25/AN25*100 -> 2.7777778 | AZ25: =AJ25/AN25*100 -> 0
