Workbook

Sheet Reporte_Epi_gestion 2025
A4: SITUACION EPIDEMIOLOGICA DE ARBOVIROSIS DPTO. CHUQUISACA GESTION 2025
A6: DENGUE
A87: CHIKUNGUNYA
A149: ZIKA
A211: Fuente: Estadistica / Area Control de Vectores - SEDES Chuquisaca

Sheet Datos Gestiones
B2: DENGUE | C2: 2009 | D2: 2010 | E2: 2011 | F2: 2012 | G2: 2013 | H2: 2014 | I2: 2015 | J2: 2016 | K2: 2017 | L2: 2018 | M2: 2019 | N2: 2020 | O2: 2021 | P2: 2022 | Q2: 2023 | R2: 2024 | S2: 2025
B3: Poblacion | C3: =214913+26504+12562+10007+10748+7386 -> 282120 | D3: =214913+26504+10007+(3269) -> 254693 | E3: 365936 | F3: 368887 | G3: 367102 | H3: 354407 | I3: 362175 | J3: 399115 | K3: 361001 | L3: 361547 | M3: 362220 | N3: 363462 | O3: 364148 | P3: 364385 | Q3: 366642 | R3: 367712 | S3: 367712
B4: Sospechosos | C4: 979 | D4: 52 | E4: 174 | F4: 443 | G4: 318 | H4: 912 | I4: 535 | J4: 574 | K4: 231 | L4: =+'Datos Semana'!BC8 -> 213 | M4: ='Datos Semana'!BD13 -> 221 | N4: ='Datos Semana'!BD18 -> 4110 | O4: ='Datos Semana'!BD23 -> 242 | P4: ='Datos Semana'!BD28 -> 650 | Q4: ='Datos Semana'!BD32 -> 4981 | R4: ='Datos Semana'!BD36 -> 1436 | S4: ='Datos Semana'!BD40 -> 701
B5: Positivos | C5: 370 | D5: 3 | E5: 38 | F5: 189 | G5: 59 | H5: 139 | I5: 15 | J5: 39 | K5: 20 | L5: =+'Datos Semana'!BC9 -> 9 | M5: ='Datos Semana'!BD14 -> 55 | N5: 2589 | O5: ='Datos Semana'!BD24 -> 27 | P5: ='Datos Semana'!BD29 -> 102 | Q5: ='Datos Semana'!BD33 -> 2077 | R5: ='Datos Semana'!BD37 -> 325 | S5: ='Datos Semana'!BD41 -> 123
B6: TI | C6: =C5/C3*10000 -> 13.114987 | D6: =D5/D3*10000 -> 0.11778887 | E6: =E5/E3*10000 -> 1.038433 | F6: =F5/F3*10000 -> 5.1235202 | G6: =G5/G3*10000 -> 1.6071827 | H6: =H5/H3*10000 -> 3.9220444 | I6: =I5/I3*10000 -> 0.41416442 | J6: =J5/J3*10000 -> 0.97716197 | ... S6: =S5/S3*10000 -> 3.3450091
B8: CHIKUNGUNYA | C8: 2015 | D8: 2016 | E8: 2017 | F8: 2018 | G8: 2019 | H8: 2020 | I8: 2021 | J8: 2022 | K8: 2023 | L8: 2024 | M8: 2025
B9: Poblacion | C9: 338134 | D9: 3008689 | E9: 295021 | F9: 329219 | G9: 322084 | H9: 305933 | I9: 305933 | J9: 305933 | K9: 305933 | L9: 305933 | M9: 305933
B10: Sospechosos | C10: 82 | D10: 373 | E10: 174 | F10: =+'Datos Semana'!BC96 -> 159 | G10: ='Datos Semana'!BD101 -> 59 | H10: ='Datos Semana'!BD105 -> 353 | I10: ='Datos Semana'!BD110 -> 39 | J10: ='Datos Semana'!BD115 -> 57 | K10: ='Datos Semana'!BD119 -> 184 | L10: ='Datos Semana'!BD123 -> 15 | M10: ='Datos Semana'!BD127 -> 131
B11: Positivos | C11: 11 | D11: 19 | E11: 2 | F11: =+'Datos Semana'!BC97 -> 4 | G11: ='Datos Semana'!BD102 -> 3 | H11: ='Datos Semana'!BD106 -> 5 | I11: ='Datos Semana'!BD111 -> 0 | J11: ='Datos Semana'!BD116 -> 0 | K11: ='Datos Semana'!BD120 -> 1 | L11: 0 | M11: ='Datos Semana'!BD128 -> 16
B12: TI | C12: =C11/C9*10000 -> 0.32531482 | D12: =D11/D9*10000 -> 0.063150429 | E12: =E11/E9*10000 -> 0.067791784 | F12: =F11/F9*10000 -> 0.12149967 | G12: =G11/G9*10000 -> 0.093143404 | H12: =H11/H9*10000 -> 0.16343448 | I12: =I11/I9*10000 -> 0 | J12: =J11/J9*10000 -> 0 | ... M12: =M11/M9*10000 -> 0.52299033
B15: ZIKA | C15: 2016 | D15: 2017 | E15: 2018 | F15: 2019 | G15: 2020 | H15: 2021 | I15: 2022 | J15: 2023 | K15: 2024 | L15: 2025
B16: Poblacion | C16: 2954981 | D16: 321075 | E16: 313179 | F16: 295353 | G16: 295353 | H16: 295353 | I16: 295353 | J16: 295353 | K16: 295353 | L16: 295353
B17: Sospechosos | C17: 152 | D17: 91 | E17: =+'Datos Semana'!BC173 -> 121 | F17: ='Datos Semana'!BD178 -> 41 | G17: ='Datos Semana'!BD182 -> 230 | H17: ='Datos Semana'!BD187 -> 30 | I17: ='Datos Semana'!BD191 -> 49 | J17: ='Datos Semana'!BD195 -> 141 | K17: ='Datos Semana'!BD199 -> 5 | L17: ='Datos Semana'!BD203 -> 74
B18: Positivos | C18: 1 | D18: 5 | E18: =+'Datos Semana'!BC174 -> 11 | F18: ='Datos Semana'!BD179 -> 1 | G18: ='Datos Semana'!BD183 -> 0 | H18: ='Datos Semana'!BD188 -> 0 | I18: ='Datos Semana'!BD192 -> 0 | J18: ='Datos Semana'!BD196 -> 0 | K18: ='Datos Semana'!BD200 -> 0 | L18: ='Datos Semana'!BD204 -> 0
B19: TI | C19: =C18/C16*10000 -> 0.0033841165 | D19: =D18/D16*10000 -> 0.15572686 | E19: =E18/E16*10000 -> 0.35123683 | F19: =F18/F16*10000 -> 0.033857791 | G19: =G18/G16*10000 -> 0 | H19: =H18/H16*10000 -> 0 | I19: =I18/I16*10000 -> 0 | J19: =J18/J16*10000 -> 0 | ... L19: =L18/L16*10000 -> 0

Sheet Hoja1
G7: DATOS
G8: POBLACION EN RIESGO | H8: 367712
G9: MUNICIPIOS | H9: 17
G10: ESTABLECIMIENTOS DE SALUD | H10: 50
G11: COMUNIDADES - BARRIOS | H11: 120

Sheet Datos 2025
C2: Dengue
C3: Municipio | D3: Sospechosos | E3: Positivos
C4: Monteagudo | D4: 460 | E4: 79
C5: Sucre | D5: 63 | E5: 1
C6: Huacareta | D6: 56 | E6: 37
C7: Huacaya | D7: 48 | E7: 5
C8: Villa Vacaguzman | D8: 36 | E8: 1
C9: Machareti | D9: 16 | E9: 0
C10: El Villar | D10: 4 | E10: 0
C11: Presto | D11: 3 | E11: 0
C12: Padilla | D12: 3 | E12: 0
C13: Alcala | D13: 3 | E13: 0
C14: Camargo | D14: 2 | E14: 0
C15: Yamparaez | D15: 2 | E15: 0
... C20: Villa Serrano | D20: 1 | E20: 0
C21: Total general | D21: =SUM(D4:D20) -> 701 | E21: =SUM(E4:E20) -> 123
C25: chik
C26: Municipio | D26: Sospechosos | E26: Positivos
C27: Machareti | D27: 14 | E27: 6
C28: Sucre | D28: 8 | E28: 5
C29: Monteagudo | D29: 55 | E29: 3
C30: Villa Vacaguzman | D30: 51 | E30: 1
C31: Tarabuco | D31: 1 | E31: 1
C32: Alcala | D32: 1 | E32: 0
C33: Total general | D33: =SUM(D27:D32) -> 130 | E33: =SUM(E27:E32) -> 16
C36: Zika
C37: Municipio | D37: Sospechosos | E37: Positivos
C38: Monteagudo | D38: 14 | E38: 0
C39: Villa Vacaguzman | D39: 51 | E39: 0
C40: Sucre | D40: 6 | E40: 0
C41: Machareti | D41: 3 | E41: 0
C42: Alcala | D42: 1 | E42: 0
C43: Total general | D43: =SUM(D38:D42) -> 75 | E43: =SUM(E38:E42) -> 0
C46: Microcefalia
C47: Municipio | D47: Sospechosos | E47: Positivos
C48: Sucre | D48: 1 | E48: 0
C49: Total general | D49: =SUM(D48:D48) -> 1 | E49: =SUM(E48:E48) -> 0
B51: DENGUE | C51: Acumulado | D51: Sexo | G51: Sem 26
C52: Edad | D52: Femenino | E52: Masculino | F52: Total general | G52: Femenino | H52: Masculino | I52: Total general
C53: 1-4 | D53: 2 | E53: 2 | F53: =D53+E53 -> 4 | G53: 0 | H53: 0 | I53: =SUM(G53:H53) -> 0
...

Sheet Hoja2
D1: 2022 | E1: 2022 | F1: 2023 | G1: 2023
A2: Red De Salud | B2: Municipio | C2: poblacion | D2: casos | E2: ti | F2: casos | G2: ti
A3: Red de Salud I Sucre Capi | B3: Sucre | C3: 367216 | D3: 7 | E3: =D3/C3*10000 -> 0.1906235 | F3: 165 | G3: =F3/C3*10000 -> 4.4932683
A4: Red de Salud II Tarabuco | B4: Icla | C4: 8051 | D4: 0 | E4: =D4/C4*10000 -> 0 | F4: 3 | G4: =F4/C4*10000 -> 3.7262452
B5: Presto | C5: 9982 | D5: 0 | E5: =D5/C5*10000 -> 0 | F5: 2 | G5: =F5/C5*10000 -> 2.0036065
B6: Tarabuco | C6: 15262 | D6: 0 | E6: =D6/C6*10000 -> 0 | F6: 9 | G6: =F6/C6*10000 -> 5.8969991
B7: Yamparaez | C7: 8459 | D7: 0 | E7: =D7/C7*10000 -> 0 | F7: 2 | G7: =F7/C7*10000 -> 2.3643457
B8: Zudañez | C8: 7598 | D8: 0 | E8: =D8/C8*10000 -> 0 | F8: 1 | G8: =F8/C8*10000 -> 1.3161358
B9: Mojocoya | C9: 7845 | D9: 0 | E9: =D9/C9*10000 -> 0 | F9: 0 | G9: =F9/C9*10000 -> 0
A10: Red de Salud III Padilla | B10: Alcala | C10: 2621 | D10: 0 | E10: =D10/C10*10000 -> 0 | F10: 3 | G10: =F10/C10*10000 -> 11.446013
B11: El Villar | C11: 3963 | D11: 0 | E11: =D11/C11*10000 -> 0 | F11: 2 | G11: =F11/C11*10000 -> 5.0466818
B12: Padilla | C12: 10230 | D12: 0 | E12: =D12/C12*10000 -> 0 | F12: 11 | G12: =F12/C12*10000 -> 10.752688
B13: Tomina | C13: 9068 | D13: 0 | E13: =D13/C13*10000 -> 0 | F13: 5 | G13: =F13/C13*10000 -> 5.513895
B14: Villa Serrano | C14: 10212 | D14: 0 | E14: =D14/C14*10000 -> 0 | F14: 15 | G14: =F14/C14*10000 -> 14.688602
A15: Red de Salud IV Azurduy | B15: Sopachuy | C15: 6057 | D15: 0 | E15: =D15/C15*10000 -> 0 | F15: 1 | G15: =F15/C15*10000 -> 1.6509823
B16: Azurduy | C16: 11239 | D16: 0 | E16: =D16/C16*10000 -> 0 | F16: 0 | G16: =F16/C16*10000 -> 0
B17: Tarvita | C17: 13882 | D17: 0 | E17: =D17/C17*10000 -> 0 | F17: 0 | G17: =F17/C17*10000 -> 0
A18: Red de Salud V Monteagudo | B18: Huacareta | C18: 8268 | D18: 6 | E18: =D18/C18*10000 -> 7.256894 | F18: 115 | G18: =F18/C18*10000 -> 139.09047
B19: Huacaya | C19: 2499 | D19: 13 | E19: =D19/C19*10000 -> 52.020808 | F19: 38 | G19: =F19/C19*10000 -> 152.06082
B20: Machareti | C20: 7154 | D20: 2 | E20: =D20/C20*10000 -> 2.7956388 | F20: 249 | G20: =F20/C20*10000 -> 348.05703
B21: Monteagudo | C21: 25324 | D21: 65 | E21: =D21/C21*10000 -> 25.667351 | F21: 1109 | G21: =F21/C21*10000 -> 437.9245
B22: Villa Vacaguzman | C22: 9462 | D22: 1 | E22: =D22/C22*10000 -> 1.056859 | F22: 183 | G22: =F22/C22*10000 -> 193.4052
A23: Red de Salud VI Camargo | B23: Camargo | C23: 15599 | D23: 0 | E23: =D23/C23*10000 -> 0 | F23: 2 | G23: =F23/C23*10000 -> 1.2821335
B24: Incahuasi | C24: 12635 | D24: 0 | E24: =D24/C24*10000 -> 0 | F24: 6 | G24: =F24/C24*10000 -> 4.7487139
B25: San Lucas | C25: 31456 | D25: 0 | E25: =D25/C25*10000 -> 0 | F25: 1 | G25: =F25/C25*10000 -> 0.31790437
B26: Villa Charcas | C26: 15644 | D26: 0 | E26: =D26/C26*10000 -> 0 | F26: 0 | G26: =F26/C26*10000 -> 0
B27: Villa Abecia | C27: 3351 | D27: 0 | E27: =D27/C27*10000 -> 0 | F27: 0 | G27: =F27/C27*10000 -> 0
B28: Las Carreras | C28: 3037 | D28: 0 | E28: =D28/C28*10000 -> 0 | F28: 0 | G28: =F28/C28*10000 -> 0
A29: Red de Salud VII Rural | B29: Poroma | C29: 15759 | D29: 0 | E29: =D29/C29*10000 -> 0 | F29: 2 | G29: =F29/C29*10000 -> 1.2691161
B30: Sucre | C30: 6423.7063 | D30: 8 | E30: =D30/C30*10000 -> 12.45387 | F30: 145 | G30: =F30/C30*10000 -> 225.72639
B31: Yotala | C31: 9129 | D31: 0 | E31: =D31/C31*10000 -> 0 | F31: 6 | G31: =F31/C31*10000 -> 6.5724614
A32: Total general | C32: 668321 | D32: =SUM(D3:D31) -> 102 | E32: =SUM(E3:E31) -> 101.44204 | F32: =SUM(F3:F31) -> 2075 | G32: =SUM(G3:G31) -> 1579.3542

Sheet Datos Semana
A1: DENGUE
A2: 2017 | B2: 1 | C2: 2 | D2: 3 | E2: 4 | F2: 5 | G2: 6 | H2: 7 | I2: 8 | J2: 9 | K2: 10 | L2: 11 | M2: 12 | N2: 13 | O2: 14 | P2: 15 | Q2: 16 | R2: 17 | S2: 18 | T2: 19 | U2: 20 | V2: 21 | W2: 22 | X2: 23 | Y2: 24 | Z2: 25 | AA2: 26 | AB2: 27 | AC2: 28 | AD2: 29 | AE2: 30 | AF2: 31 | AG2: 32 | AH2: 33 | AI2: 34 | AJ2: 35 | AK2: 36 | AL2: 37 | AM2: 38 | AN2: 39 | AO2: 40 | AP2: 41 | AQ2: 42 | AR2: 43 | AS2: 44 | AT2: 45 | AU2: 46 | AV2: 47 | AW2: 48 | AX2: 49 | AY2: 50 | AZ2: 51 | BA2: 52 | BB2: 53 | BC2: Total
A3: Sospechosos | B3: 0 | C3: 2 | D3: 8 | E3: 5 | F3: 0 | G3: 7 | H3: 1 | I3: 4 | J3: 9 | K3: 6 | L3: 12 | M3: 18 | N3: 11 | O3: 12 | P3: 13 | Q3: 23 | R3: 7 | S3: 3 | T3: 13 | U3: 8 | V3: 2 | W3: 3 | X3: 2 | Y3: 1 | Z3: 6 | AA3: 1 | AB3: 0 | AC3: 1 | AD3: 1 | AE3: 0 | AF3: 0 | AG3: 2 | AH3: 2 | AI3: 2 | AJ3: 0 | AK3: 2 | AL3: 3 | AM3: 0 | AN3: 0 | AO3: 6 | AP3: 3 | AQ3: 3 | AR3: 1 | AS3: 3 | AT3: 0 | AU3: 5 | AV3: 3 | AW3: 2 | AX3: 4 | AY3: 4 | AZ3: 3 | BA3: 4 | BC3: =SUM(B3:BA3) -> 231
A4: Positivos | B4: 0 | C4: 0 | D4: 0 | E4: 1 | F4: 0 | G4: 0 | H4: 0 | I4: 0 | J4: 2 | K4: 1 | L4: 2 | M4: 1 | N4: 0 | O4: 1 | P4: 2 | Q4: 3 | R4: 1 | S4: 0 | T4: 1 | U4: 2 | V4: 0 | W4: 2 | X4: 1 | Y4: 0 | Z4: 0 | AA4: 0 | AB4: 0 | AC4: 0 | AD4: 0 | AE4: 0 | AF4: 0 | AG4: 0 | AH4: 0 | AI4: 0 | AJ4: 0 | AK4: 0 | AL4: 0 | AM4: 0 | AN4: 0 | AO4: 0 | AP4: 0 | AQ4: 0 | AR4: 0 | AS4: 0 | AT4: 0 | AU4: 0 | AV4: 0 | AW4: 0 | AX4: 0 | AY4: 0 | AZ4: 0 | BA4: 0 | BC4: =SUM(B4:BA4) -> 20
A7: 2018 | B7: 1 | C7: 2 | D7: 3 | E7: 4 | F7: 5 | G7: 6 | H7: 7 | I7: 8 | J7: 9 | K7: 10 | L7: 11 | M7: 12 | N7: 13 | O7: 14 | P7: 15 | Q7: 16 | R7: 17 | S7: 18 | T7: 19 | U7: 20 | V7: 21 | W7: 22 | X7: 23 | Y7: 24 | Z7: 25 | AA7: 26 | AB7: 27 | AC7: 28 | AD7: 29 | AE7: 30 | AF7: 31 | AG7: 32 | AH7: 33 | AI7: 34 | AJ7: 35 | AK7: 36 | AL7: 37 | AM7: 38 | AN7: 39 | AO7: 40 | AP7: 41 | AQ7: 42 | AR7: 43 | AS7: 44 | AT7: 45 | AU7: 46 | AV7: 47 | AW7: 48 | AX7: 49 | AY7: 50 | AZ7: 51 | BA7: 52 | BC7: Total
A8: Sospechosos | B8: 8 | C8: 6 | D8: 6 | E8: 3 | F8: 6 | G8: 3 | H8: 3 | I8: 9 | J8: 5 | K8: 18 | L8: 6 | M8: 16 | N8: 7 | O8: 15 | P8: 7 | Q8: 10 | R8: 18 | S8: 14 | T8: 5 | U8: 8 | V8: 3 | W8: 1 | X8: 0 | Y8: 0 | Z8: 1 | AA8: 2 | AB8: 1 | AC8: 1 | AD8: 0 | AE8: 0 | AF8: 2 | AG8: 0 | AH8: 0 | AI8: 0 | AJ8: 0 | AK8: 0 | AL8: 2 | AM8: 0 | AN8: 0 | AO8: 0 | AP8: 2 | AQ8: 4 | AR8: 0 | AS8: 1 | AT8: 8 | AU8: 1 | AV8: 1 | AW8: 3 | AX8: 1 | AY8: 2 | AZ8: 2 | BA8: 2 | BC8: =SUM(B8:BA8) -> 213 | BD8: =SUM(B8:BA8) -> 213
A9: Positivos | B9: 0 | C9: 0 | D9: 0 | E9: 0 | F9: 0 | G9: 0 | H9: 0 | I9: 0 | J9: 0 | K9: 0 | L9: 0 | M9: 2 | N9: 1 | O9: 1 | P9: 0 | Q9: 0 | R9: 2 | S9: 1 | T9: 0 | U9: 2 | V9: 0 | W9: 0 | X9: 0 | Y9: 0 | Z9: 0 | AA9: 0 | AB9: 0 | AC9: 0 | AD9: 0 | AE9: 0 | AF9: 0 | AG9: 0 | AH9: 0 | AI9: 0 | AJ9: 0 | AK9: 0 | AL9: 0 | AM9: 0 | AN9: 0 | AO9: 0 | AP9: 0 | AQ9: 0 | AR9: 0 | AS9: 0 | AT9: 0 | AU9: 0 | AV9: 0 | AW9: 0 | AX9: 0 | AY9: 0 | AZ9: 0 | BA9: 0 | BC9: =SUM(B9:BA9) -> 9 | BD9: =SUM(B9:BA9) -> 9
A12: 2019 | B12: 1 | C12: 2 | D12: 3 | E12: 4 | F12: 5 | G12: 6 | H12: 7 | I12: 8 | J12: 9 | K12: 10 | L12: 11 | M12: 12 | N12: 13 | O12: 14 | P12: 15 | Q12: 16 | R12: 17 | S12: 18 | T12: 19 | U12: 20 | V12: 21 | W12: 22 | X12: 23 | Y12: 24 | Z12: 25 | AA12: 26 | AB12: 27 | AC12: 28 | AD12: 29 | AE12: 30 | AF12: 31 | AG12: 32 | AH12: 33 | AI12: 34 | AJ12: 35 | AK12: 36 | AL12: 37 | AM12: 38 | AN12: 39 | AO12: 40 | AP12: 41 | AQ12: 42 | AR12: 43 | AS12: 44 | AT12: 45 | AU12: 46 | AV12: 47 | AW12: 48 | AX12: 49 | AY12: 50 | AZ12: 51 | BA12: 52 | BC12: Total
A13: Sospechosos | B13: 5 | C13: 4 | D13: 4 | E13: 4 | F13: 5 | G13: 5 | H13: 3 | I13: 9 | J13: 4 | K13: 4 | L13: 2 | M13: 8 | N13: 7 | O13: 4 | P13: 4 | Q13: 1 | R13: 5 | S13: 2 | T13: 3 | U13: 2 | V13: 3 | W13: 4 | X13: 2 | Y13: 2 | Z13: 1 | AA13: 3 | AB13: 2 | AC13: 4 | AD13: 3 | AE13: 2 | AF13: 0 | AG13: 2 | AH13: 3 | AI13: 4 | AJ13: 2 | AK13: 0 | AL13: 1 | AM13: 0 | AN13: 0 | AO13: 5 | AP13: 0 | AQ13: 4 | AR13: 1 | AS13: 4 | AT13: 3 | AU13: 3 | AV13: 2 | AW13: 7 | AX13: 4 | AY13: 10 | AZ13: 17 | BA13: 38 | BC13: =SUM(B13:BA13) -> 221 | BD13: =BC13 -> 221
A14: Positivos | B14: 0 | C14: 0 | D14: 0 | E14: 0 | F14: 1 | G14: 0 | H14: 0 | I14: 1 | J14: 2 | K14: 0 | L14: 0 | M14: 1 | N14: 0 | O14: 1 | P14: 1 | Q14: 0 | R14: 3 | S14: 0 | T14: 0 | U14: 0 | V14: 0 | W14: 0 | X14: 0 | Y14: 0 | Z14: 0 | AA14: 0 | AB14: 0 | AC14: 1 | AD14: 0 | AE14: 0 | AF14: 0 | AG14: 0 | AH14: 0 | AI14: 0 | AJ14: 0 | AK14: 0 | AL14: 0 | AM14: 0 | AN14: 0 | AO14: 0 | AP14: 0 | AQ14: 0 | AR14: 0 | AS14: 0 | AT14: 0 | AU14: 0 | AV14: 0 | AW14: 4 | AX14: 0 | AY14: 3 | AZ14: 9 | BA14: 28 | BC14: =SUM(B14:BA14) -> 55 | BD14: =BC14 -> 55
A17: 2020 Notificacion | B17: 1 | C17: 2 | D17: 3 | E17: 4 | F17: 5 | G17: 6 | H17: 7 | I17: 8 | J17: 9 | K17: 10 | L17: 11 | M17: 12 | N17: 13 | O17: 14 | P17: 15 | Q17: 16 | R17: 17 | S17: 18 | T17: 19 | U17: 20 | V17: 21 | W17: 22 | X17: 23 | Y17: 24 | Z17: 25 | AA17: 26 | AB17: 27 | AC17: 28 | AD17: 29 | AE17: 30 | AF17: 31 | AG17: 32 | AH17: 33 | AI17: 34 | AJ17: 35 | AK17: 36 | AL17: 37 | AM17: 38 | AN17: 39 | AO17: 40 | AP17: 41 | AQ17: 42 | AR17: 43 | AS17: 44 | AT17: 45 | AU17: 46 | AV17: 47 | AW17: 48 | AX17: 49 | AY17: 50 | AZ17: 51 | BA17: 52 | BB17: 53 | BC17: 2019 | BD17: 2020
A18: Sospechosos | B18: 22 | C18: 132 | D18: 197 | E18: 185 | F18: 307 | G18: 380 | H18: 440 | I18: 373 | J18: 293 | K18: 222 | L18: 269 | M18: 224 | N18: 175 | O18: 197 | P18: 215 | Q18: 128 | R18: 91 | S18: 48 | T18: 54 | U18: 40 | V18: 15 | W18: 11 | X18: 8 | Y18: 2 | Z18: 10 | AA18: 4 | AB18: 0 | AC18: 0 | AD18: 0 | AE18: 0 | AF18: 0 | AG18: 1 | AH18: 0 | AI18: 1 | AJ18: 1 | AK18: 1 | AL18: 0 | AM18: 0 | AN18: 3 | AO18: 0 | AP18: 1 | AQ18: 4 | AR18: 2 | AS18: 2 | AT18: 3 | AU18: 4 | AV18: 4 | AW18: 3 | AX18: 7 | AY18: 2 | AZ18: 12 | BA18: 13 | BB18: 4 | BC18: =SUM(B13:BA13) -> 221 | BD18: =SUM(B18:BB18) -> 4110
A19: Positivos | B19: 9 | C19: 85 | D19: 127 | E19: 126 | F19: 188 | G19: 231 | H19: 304 | I19: 217 | J19: 156 | K19: 116 | L19: 155 | M19: 152 | N19: 128 | O19: 156 | P19: 177 | Q19: 87 | R19: 68 | S19: 32 | T19: 33 | U19: 19 | V19: 9 | W19: 6 | X19: 2 | Y19: 1 | Z19: 2 | AA19: 0 | AB19: 0 | AC19: 0 | AD19: 0 | AE19: 0 | AF19: 0 | AG19: 0 | AH19: 0 | AI19: 0 | AJ19: 0 | AK19: 0 | AL19: 0 | AM19: 0 | AN19: 0 | AO19: 0 | AP19: 0 | AQ19: 0 | AR19: 0 | AS19: 0 | AT19: 0 | AU19: 0 | AV19: 0 | AW19: 0 | AX19: 0 | AY19: 1 | AZ19: 0 | BA19: 2 | BB19: 0 | BC19: =SUM(B14:BA14) -> 55 | BD19: =SUM(B19:BB19) -> 2589
A22: 2021 Notificacion | B22: 1 | C22: 2 | D22: 3 | E22: 4 | F22: 5 | G22: 6 | H22: 7 | I22: 8 | J22: 9 | K22: 10 | L22: 11 | M22: 12 | N22: 13 | O22: 14 | P22: 15 | Q22: 16 | R22: 17 | S22: 18 | T22: 19 | U22: 20 | V22: 21 | W22: 22 | X22: 23 | Y22: 24 | Z22: 25 | AA22: 26 | AB22: 27 | AC22: 28 | AD22: 29 | AE22: 30 | AF22: 31 | AG22: 32 | AH22: 33 | AI22: 34 | AJ22: 35 | AK22: 36 | AL22: 37 | AM22: 38 | AN22: 39 | AO22: 40 | AP22: 41 | AQ22: 42 | AR22: 43 | AS22: 44 | AT22: 45 | AU22: 46 | AV22: 47 | AW22: 48 | AX22: 49 | AY22: 50 | AZ22: 51 | BA22: 52 | BB22: 53 | BC22: 2020 | BD22: 2021
A23: Sospechosos | B23: 1 | C23: 12 | D23: 18 | E23: 8 | F23: 5 | G23: 4 | H23: 6 | I23: 10 | J23: 4 | K23: 15 | L23: 6 | M23: 4 | N23: 5 | O23: 15 | P23: 10 | Q23: 6 | R23: 8 | S23: 4 | T23: 6 | U23: 5 | V23: 1 | W23: 0 | X23: 0 | Y23: 5 | Z23: 3 | AA23: 1 | AB23: 1 | AC23: 2 | AD23: 1 | AE23: 2 | AF23: 0 | AG23: 0 | AH23: 2 | AI23: 0 | AJ23: 0 | AK23: 1 | AL23: 2 | AM23: 4 | AN23: 2 | AO23: 6 | AP23: 2 | AQ23: 6 | AR23: 3 | AS23: 7 | AT23: 3 | AU23: 5 | AV23: 6 | AW23: 2 | AX23: 6 | AY23: 0 | AZ23: 7 | BA23: 10 | BC23: =SUM(B18:BB18) -> 4110 | BD23: =SUM(B23:BB23) -> 242
A24: Positivos | B24: 1 | C24: 2 | D24: 3 | E24: 1 | F24: 1 | G24: 1 | H24: 1 | I24: 1 | J24: 0 | K24: 1 | L24: 0 | M24: 1 | N24: 0 | O24: 6 | P24: 2 | Q24: 0 | R24: 0 | S24: 0 | T24: 1 | U24: 1 | V24: 0 | W24: 0 | X24: 0 | Y24: 0 | Z24: 0 | AA24: 0 | AB24: 0 | AC24: 0 | AD24: 0 | AE24: 0 | AF24: 0 | AG24: 0 | AH24: 0 | AI24: 0 | AJ24: 0 | AK24: 0 | AL24: 0 | AM24: 1 | AN24: 0 | AO24: 1 | AP24: 0 | AQ24: 0 | AR24: 0 | AS24: 0 | AT24: 0 | AU24: 0 | AV24: 0 | AW24: 0 | AX24: 0 | AY24: 0 | AZ24: 2 | BA24: 0 | BC24: =SUM(B19:BB19) -> 2589 | BD24: =SUM(B24:BB24) -> 27
A27: 2022 Notificacion | B27: 1 | C27: 2 | D27: 3 | E27: 4 | F27: 5 | G27: 6 | H27: 7 | I27: 8 | J27: 9 | K27: 10 | L27: 11 | M27: 12 | N27: 13 | O27: 14 | P27: 15 | Q27: 16 | R27: 17 | S27: 18 | T27: 19 | U27: 20 | V27: 21 | W27: 22 | X27: 23 | Y27: 24 | Z27: 25 | AA27: 26 | AB27: 27 | AC27: 28 | AD27: 29 | AE27: 30 | AF27: 31 | AG27: 32 | AH27: 33 | AI27: 34 | AJ27: 35 | AK27: 36 | AL27: 37 | AM27: 38 | AN27: 39 | AO27: 40 | AP27: 41 | AQ27: 42 | AR27: 43 | AS27: 44 | AT27: 45 | AU27: 46 | AV27: 47 | AW27: 48 | AX27: 49 | AY27: 50 | AZ27: 51 | BA27: 52 | BC27: 2021 | BD27: 2022
A28: Sospechosos | B28: 13 | C28: 8 | D28: 19 | E28: 7 | F28: 2 | G28: 10 | H28: 6 | I28: 9 | J28: 23 | K28: 29 | L28: 32 | M28: 31 | N28: 16 | O28: 21 | P28: 15 | Q28: 24 | R28: 33 | S28: 16 | T28: 44 | U28: 21 | V28: 6 | W28: 1 | X28: 1 | Y28: 5 | Z28: 6 | AA28: 2 | AB28: 11 | AC28: 7 | AD28: 13 | AE28: 0 | AF28: 1 | AG28: 1 | AH28: 0 | AI28: 0 | AJ28: 2 | AK28: 2 | AL28: 0 | AM28: 1 | AN28: 4 | AO28: 6 | AP28: 6 | AQ28: 8 | AR28: 17 | AS28: 10 | AT28: 23 | AU28: 22 | AV28: 20 | AW28: 21 | AX28: 22 | AY28: 32 | AZ28: 5 | BA28: 16 | BC28: =SUM(B23:BA23) -> 242 | BD28: =SUM(B28:BB28) -> 650
A29: Positivos | B29: 0 | C29: 0 | D29: 0 | E29: 0 | F29: 0 | G29: 0 | H29: 0 | I29: 4 | J29: 9 | K29: 14 | L29: 15 | M29: 8 | N29: 3 | O29: 1 | P29: 3 | Q29: 4 | R29: 13 | S29: 4 | T29: 8 | U29: 6 | V29: 0 | W29: 0 | X29: 0 | Y29: 2 | Z29: 0 | AA29: 0 | AB29: 0 | AC29: 0 | AD29: 0 | AE29: 0 | AF29: 0 | AG29: 0 | AH29: 0 | AI29: 0 | AJ29: 0 | AK29: 0 | AL29: 0 | AM29: 0 | AN29: 0 | AO29: 0 | AP29: 0 | AQ29: 0 | AR29: 0 | AS29: 0 | AT29: 0 | AU29: 0 | AV29: 1 | AW29: 0 | AX29: 2 | AY29: 1 | AZ29: 2 | BA29: 2 | BC29: =SUM(B24:BA24) -> 27 | BD29: =SUM(B29:BB29) -> 102
A31: 2023 Notificacion | B31: 1 | C31: 2 | D31: 3 | E31: 4 | F31: 5 | G31: 6 | H31: 7 | I31: 8 | J31: 9 | K31: 10 | L31: 11 | M31: 12 | N31: 13 | O31: 14 | P31: 15 | Q31: 16 | R31: 17 | S31: 18 | T31: 19 | U31: 20 | V31: 21 | W31: 22 | X31: 23 | Y31: 24 | Z31: 25 | AA31: 26 | AB31: 27 | AC31: 28 | AD31: 29 | AE31: 30 | AF31: 31 | AG31: 32 | AH31: 33 | AI31: 34 | AJ31: 35 | AK31: 36 | AL31: 37 | AM31: 38 | AN31: 39 | AO31: 40 | AP31: 41 | AQ31: 42 | AR31: 43 | AS31: 44 | AT31: 45 | AU31: 46 | AV31: 47 | AW31: 48 | AX31: 49 | AY31: 50 | AZ31: 51 | BA31: 52 | BC31: 2022 | BD31: 2023
A32: Sospechosos | B32: 21 | C32: 19 | D32: 52 | E32: 75 | F32: 135 | G32: 198 | H32: 194 | I32: 216 | J32: 263 | K32: 371 | L32: 415 | M32: 400 | N32: 343 | O32: 392 | P32: 398 | Q32: 313 | R32: 247 | S32: 189 | T32: 188 | U32: 78 | V32: 74 | W32: 84 | X32: 67 | Y32: 31 | Z32: 16 | AA32: 13 | AB32: 7 | AC32: 6 | AD32: 4 | AE32: 3 | AF32: 6 | AG32: 5 | AH32: 4 | AI32: 2 | AJ32: 2 | AK32: 11 | AL32: 6 | AM32: 8 | AN32: 5 | AO32: 3 | AP32: 5 | AQ32: 3 | AR32: 10 | AS32: 4 | AT32: 9 | AU32: 8 | AV32: 0 | AW32: 14 | AX32: 12 | AY32: 22 | AZ32: 11 | BA32: 19 | BC32: =SUM(A28:BA28) -> 650 | BD32: =SUM(A32:BA32) -> 4981
A33: Positivos | B33: 4 | C33: 2 | D33: 11 | E33: 21 | F33: 57 | G33: 78 | H33: 97 | I33: 88 | J33: 78 | K33: 175 | L33: 130 | M33: 283 | N33: 140 | O33: 194 | P33: 220 | Q33: 170 | R33: 86 | S33: 98 | T33: 37 | U33: 24 | V33: 21 | W33: 21 | X33: 19 | Y33: 9 | Z33: 2 | AA33: 3 | AB33: 4 | AC33: 2 | AD33: 0 | AE33: 0 | AF33: 1 | AG33: 0 | AH33: 0 | AI33: 0 | AJ33: 0 | AK33: 0 | AL33: 0 | AM33: 0 | AN33: 0 | AO33: 0 | AP33: 0 | AQ33: 0 | AR33: 0 | AS33: 0 | AT33: 0 | AU33: 1 | AV33: 0 | AW33: 0 | AX33: 0 | AY33: 0 | AZ33: 1 | BA33: 0 | BC33: =SUM(A29:BA29) -> 102 | BD33: =SUM(A33:BA33) -> 2077
A35: 2024 Notificacion | B35: 1 | C35: 2 | D35: 3 | E35: 4 | F35: 5 | G35: 6 | H35: 7 | I35: 8 | J35: 9 | K35: 10 | L35: 11 | M35: 12 | N35: 13 | O35: 14 | P35: 15 | Q35: 16 | R35: 17 | S35: 18 | T35: 19 | U35: 20 | V35: 21 | W35: 22 | X35: 23 | Y35: 24 | Z35: 25 | AA35: 26 | AB35: 27 | AC35: 28 | AD35: 29 | AE35: 30 | AF35: 31 | AG35: 32 | AH35: 33 | AI35: 34 | AJ35: 35 | AK35: 36 | AL35: 37 | AM35: 38 | AN35: 39 | AO35: 40 | AP35: 41 | AQ35: 42 | AR35: 43 | AS35: 44 | AT35: 45 | AU35: 46 | AV35: 47 | AW35: 48 | AX35: 49 | AY35: 50 | AZ35: 51 | BA35: 52 | BC35: 2023 | BD35: 2024
A36: Sospechosos | B36: 27 | C36: 38 | D36: 25 | E36: 25 | F36: 36 | G36: 25 | H36: 26 | I36: 35 | J36: 28 | K36: 33 | L36: 51 | M36: 63 | N36: 72 | O36: 102 | P36: 103 | Q36: 98 | R36: 90 | S36: 98 | T36: 85 | U36: 68 | V36: 37 | W36: 12 | X36: 12 | Y36: 10 | Z36: 21 | AA36: 13 | AB36: 4 | AC36: 5 | AD36: 3 | AE36: 3 | AF36: 3 | AG36: 4 | AH36: 1 | AI36: 1 | AJ36: 0 | AK36: 1 | AL36: 6 | AM36: 9 | AN36: 27 | AO36: 20 | AP36: 14 | AQ36: 18 | AR36: 20 | AS36: 17 | AT36: 11 | AU36: 2 | AV36: 3 | AW36: 9 | AX36: 1 | AY36: 2 | AZ36: 13 | BA36: 6 | BC36: =SUM(B32:AZ32) -> 4962 | BD36: =SUM(A36:BA36) -> 1436
A37: Positivos | B37: 1 | C37: 2 | D37: 1 | E37: 0 | F37: 3 | G37: 1 | H37: 7 | I37: 2 | J37: 3 | K37: 1 | L37: 9 | M37: 12 | N37: 13 | O37: 43 | P37: 33 | Q37: 42 | R37: 23 | S37: 31 | T37: 39 | U37: 22 | V37: 12 | W37: 7 | X37: 1 | Y37: 0 | Z37: 8 | AA37: 5 | AB37: 1 | AC37: 2 | AD37: 1 | AE37: 0 | AF37: 0 | AG37: 0 | AH37: 0 | AI37: 0 | AJ37: 0 | AK37: 0 | AL37: 0 | AM37: 0 | AN37: 0 | AO37: 0 | AP37: 0 | AQ37: 0 | AR37: 0 | AS37: 0 | AT37: 0 | AU37: 0 | AV37: 0 | AW37: 0 | AX37: 0 | AY37: 0 | AZ37: 0 | BA37: 0 | BC37: =SUM(B33:AZ33) -> 2077 | BD37: =SUM(A37:BA37) -> 325
A39: 2025 | B39: 1 | C39: 2 | D39: 3 | E39: 4 | F39: 5 | G39: 6 | H39: 7 | I39: 8 | J39: 9 | K39: 10 | L39: 11 | M39: 12 | N39: 13 | O39: 14 | P39: 15 | Q39: 16 | R39: 17 | S39: 18 | T39: 19 | U39: 20 | V39: 21 | W39: 22 | X39: 23 | Y39: 24 | Z39: 25 | AA39: 26 | AB39: 27 | AC39: 28 | AD39: 29 | AE39: 30 | AF39: 31 | AG39: 32 | AH39: 33 | AI39: 34 | AJ39: 35 | AK39: 36 | AL39: 37 | AM39: 38 | AN39: 39 | AO39: 40 | AP39: 41 | AQ39: 42 | AR39: 43 | AS39: 44 | AT39: 45 | AU39: 46 | AV39: 47 | AW39: 48 | AX39: 49 | AY39: 50 | AZ39: 51 | BA39: 52 | BB39: 53 | BC39: Total 2023 | BD39: Total 2024
A40: Sospechosos | B40: 16 | C40: 9 | D40: 13 | E40: 13 | F40: 8 | G40: 15 | H40: 14 | I40: 17 | J40: 30 | K40: 18 | L40: 34 | M40: 37 | N40: 56 | O40: 43 | P40: 45 | Q40: 49 | R40: 26 | S40: 21 | T40: 21 | U40: 26 | V40: 15 | W40: 13 | X40: 9 | Y40: 7 | Z40: 4 | AA40: 5 | AB40: 5 | AC40: 3 | AD40: 3 | AE40: 2 | AF40: 3 | AG40: 2 | AH40: 1 | AI40: 4 | AJ40: 2 | AK40: 3 | AL40: 2 | AM40: 3 | AN40: 2 | AO40: 5 | AP40: 4 | AQ40: 2 | AR40: 6 | AS40: 2 | AT40: 4 | AU40: 10 | AV40: 7 | AW40: 14 | AX40: 4 | AY40: 12 | AZ40: 14 | BA40: 9 | BB40: 9 | BC40: =SUM(B36:BB36) -> 1436 | BD40: =SUM(B40:BB40) -> 701
A41: Positivos | B41: 0 | C41: 0 | D41: 0 | E41: 1 | F41: 0 | G41: 0 | H41: 1 | I41: 2 | J41: 4 | K41: 5 | L41: 13 | M41: 12 | N41: 20 | O41: 18 | P41: 12 | Q41: 5 | R41: 3 | S41: 4 | T41: 5 | U41: 7 | V41: 4 | W41: 4 | X41: 1 | Y41: 0 | Z41: 0 | AA41: 0 | AB41: 1 | AC41: 1 | AD41: 0 | AE41: 0 | AF41: 0 | AG41: 0 | AH41: 0 | AI41: 0 | AJ41: 0 | AK41: 0 | AL41: 0 | AM41: 0 | AN41: 0 | AO41: 0 | AP41: 0 | AQ41: 0 | AR41: 0 | AS41: 0 | AT41: 0 | AU41: 0 | AV41: 0 | AW41: 0 | AX41: 0 | AY41: 0 | AZ41: 0 | BA41: 0 | BB41: 0 | BC41: =SUM(B37:BA37) -> 325 | BD41: =SUM(B41:BB41) -> 123
A44: Periodo epidemico 2018 -2019 | B44: 35 | C44: 36 | D44: 37 | E44: 38 | F44: 39 | G44: 40 | H44: 41 | I44: 42 | J44: 43 | K44: 44 | L44: 45 | M44: 46 | N44: 47 | O44: 48 | P44: 49 | Q44: 50 | R44: 51 | S44: 52 | T44: 1 | U44: 2 | V44: 3 | W44: 4 | X44: 5 | Y44: 6 | Z44: 7 | AA44: 8 | AB44: 9 | AC44: 10 | AD44: 11 | AE44: 12 | AF44: 13 | AG44: 14 | AH44: 15 | AI44: 16 | AJ44: 17 | AK44: 18 | AL44: 19 | AM44: 20 | AN44: 21 | AO44: 22 | AP44: 23 | AQ44: 24 | AR44: 25 | AS44: 26 | AT44: 27 | AU44: 28 | AV44: 29 | AW44: 30 | AX44: 31 | AY44: 32 | AZ44: 33 | BA44: 34
A45: Sospechosos | B45: 0 | C45: 0 | D45: 2 | E45: 0 | F45: 0 | G45: 0 | H45: 2 | I45: 4 | J45: 0 | K45: 1 | L45: 8 | M45: 1 | N45: 1 | O45: 3 | P45: 1 | Q45: 2 | R45: 2 | S45: 2 | T45: =B13 -> 5 | U45: =C13 -> 4 | V45: =D13 -> 4 | W45: =E13 -> 4 | X45: =F13 -> 5 | Y45: =G13 -> 5 | Z45: =H13 -> 3 | AA45: =I13 -> 9 | ... BA45: =AI13 -> 4 | BN45: =SUM(B45:BA45) -> 149
A46: Positivos | B46: 0 | C46: 0 | D46: 0 | E46: 0 | F46: 0 | G46: 0 | H46: 0 | I46: 0 | J46: 0 | K46: 0 | L46: 0 | M46: 0 | N46: 0 | O46: 0 | P46: 0 | Q46: 0 | R46: 0 | S46: 0 | T46: =B14 -> 0 | U46: =C14 -> 0 | V46: =D14 -> 0 | W46: =E14 -> 0 | X46: =F14 -> 1 | Y46: =G14 -> 0 | Z46: =H14 -> 0 | AA46: =I14 -> 1 | ... BA46: =AI14 -> 0 | BN46: =SUM(B46:BA46) -> 11
A50: Periodo epidemico 2019 -2020 | B50: 35 | C50: 36 | D50: 37 | E50: 38 | F50: 39 | G50: 40 | H50: 41 | I50: 42 | J50: 43 | K50: 44 | L50: 45 | M50: 46 | N50: 47 | O50: 48 | P50: 49 | Q50: 50 | R50: 51 | S50: 52 | T50: 1 | U50: 2 | V50: 3 | W50: 4 | X50: 5 | Y50: 6 | Z50: 7 | AA50: 8 | AB50: 9 | AC50: 10 | AD50: 11 | AE50: 12 | AF50: 13 | AG50: 14 | AH50: 15 | AI50: 16 | AJ50: 17 | AK50: 18 | AL50: 19 | AM50: 20 | AN50: 21 | AO50: 22 | AP50: 23 | AQ50: 24 | AR50: 25 | AS50: 26 | AT50: 27 | AU50: 28 | AV50: 29 | AW50: 30 | AX50: 31 | AY50: 32 | AZ50: 33 | BA50: 34 | BN50: 2018-2019 | BO50: 2019-2020
A51: Sospechosos | B51: 2 | C51: 0 | D51: 1 | E51: 0 | F51: 0 | G51: 5 | H51: 0 | I51: 4 | J51: 1 | K51: 4 | L51: 3 | M51: 3 | N51: 2 | O51: 7 | P51: 4 | Q51: 10 | R51: 17 | S51: 37 | T51: =B18 -> 22 | U51: =C18 -> 132 | V51: =D18 -> 197 | W51: =E18 -> 185 | X51: =F18 -> 307 | Y51: =G18 -> 380 | Z51: =H18 -> 440 | AA51: =I18 -> 373 | ... BA51: =AI18 -> 1 | BN51: =BN45 -> 149 | BO51: =SUM(B51:AM51) -> 4092
A52: Positivos | B52: 0 | C52: 0 | D52: 0 | E52: 0 | F52: 0 | G52: 0 | H52: 0 | I52: 0 | J52: 0 | K52: 0 | L52: 0 | M52: 0 | N52: 0 | O52: 4 | P52: 0 | Q52: 3 | R52: 9 | S52: 28 | T52: =B19 -> 9 | U52: =C19 -> 85 | V52: =D19 -> 127 | W52: =E19 -> 126 | X52: =F19 -> 188 | Y52: =G19 -> 231 | Z52: =H19 -> 304 | AA52: =I19 -> 217 | ... BA52: =AI19 -> 0 | BN52: =BN46 -> 11 | BO52: =SUM(B52:AM52) -> 2610
A54: Periodo epidemico 2020 -2021 | B54: 35 | C54: 36 | D54: 37 | E54: 38 | F54: 39 | G54: 40 | H54: 41 | I54: 42 | J54: 43 | K54: 44 | L54: 45 | M54: 46 | N54: 47 | O54: 48 | P54: 49 | Q54: 50 | R54: 51 | S54: 52 | T54: 53 | U54: 1 | V54: 2 | W54: 3 | X54: 4 | Y54: 5 | Z54: 6 | AA54: 7 | AB54: 8 | AC54: 9 | AD54: 10 | AE54: 11 | AF54: 12 | AG54: 13 | AH54: 14 | AI54: 15 | AJ54: 16 | AK54: 17 | AL54: 18 | AM54: 19 | AN54: 20 | AO54: 21 | AP54: 22 | AQ54: 23 | AR54: 24 | AS54: 25 | AT54: 26 | AU54: 27 | AV54: 28 | AW54: 29 | AX54: 30 | AY54: 31 | AZ54: 32 | BA54: 33 | BB54: 34 | BN54: 2019-2020 | BO54: 2020-2021
A55: Sospechosos | B55: =AJ18 -> 1 | C55: =AK18 -> 1 | D55: =AL18 -> 0 | E55: =AM18 -> 0 | F55: =AN18 -> 3 | G55: =AO18 -> 0 | H55: =AP18 -> 1 | I55: =AQ18 -> 4 | ... T55: =BB18 -> 4 | U55: =B23 -> 1 | V55: =C23 -> 12 | W55: =D23 -> 18 | X55: =E23 -> 8 | Y55: =F23 -> 5 | Z55: =G23 -> 4 | AA55: =H23 -> 6 | AB55: =I23 -> 10 | ... BB55: =AI23 -> 0 | BN55: =SUM(B51:AZ51) -> 4143 | BO55: =SUM(B55:BA55) -> 236
A56: Positivos | B56: =AJ19 -> 0 | C56: =AK19 -> 0 | D56: =AL19 -> 0 | E56: =AM19 -> 0 | F56: =AN19 -> 0 | G56: =AO19 -> 0 | H56: =AP19 -> 0 | I56: 0 | J56: =AR19 -> 0 | K56: =AS19 -> 0 | L56: =AT19 -> 0 | M56: =AU19 -> 0 | N56: =AV19 -> 0 | O56: =AW19 -> 0 | P56: =AX19 -> 0 | Q56: =AY19 -> 1 | ... T56: =BB19 -> 0 | U56: =B24 -> 1 | V56: =C24 -> 2 | W56: =D24 -> 3 | X56: =E24 -> 1 | Y56: =F24 -> 1 | Z56: =G24 -> 1 | AA56: =H24 -> 1 | AB56: =I24 -> 1 | ... BB56: =AI24 -> 0 | BN56: =SUM(B52:AZ52) -> 2630 | BO56: =SUM(B56:BA56) -> 26
A59: Periodo epidemico 2021 -2022 | B59: 35 | C59: 36 | D59: 37 | E59: 38 | F59: 39 | G59: 40 | H59: 41 | I59: 42 | J59: 43 | K59: 44 | L59: 45 | M59: 46 | N59: 47 | O59: 48 | P59: 49 | Q59: 50 | R59: 51 | S59: 52 | T59: 1 | U59: 2 | V59: 3 | W59: 4 | X59: 5 | Y59: 6 | Z59: 7 | AA59: 8 | AB59: 9 | AC59: 10 | AD59: 11 | AE59: 12 | AF59: 13 | AG59: 14 | AH59: 15 | AI59: 16 | AJ59: 17 | AK59: 18 | AL59: 19 | AM59: 20 | AN59: 21 | AO59: 22 | AP59: 23 | AQ59: 24 | AR59: 25 | AS59: 26 | AT59: 27 | AU59: 28 | AV59: 29 | AW59: 30 | AX59: 31 | AY59: 32 | AZ59: 33 | BA59: 34 | BN59: 2020-2021 | BO59: 2021-2022
A60: Sospechosos | B60: =AJ23 -> 0 | C60: =AK23 -> 1 | D60: =AL23 -> 2 | E60: =AM23 -> 4 | F60: =AN23 -> 2 | G60: =AO23 -> 6 | H60: =AP23 -> 2 | I60: =AQ23 -> 6 | ... S60: =BA23 -> 10 | T60: =B28 -> 13 | U60: =C28 -> 8 | V60: =D28 -> 19 | W60: =E28 -> 7 | X60: =F28 -> 2 | Y60: =G28 -> 10 | Z60: =H28 -> 6 | AA60: =I28 -> 9 | ... BA60: =AI28 -> 0 | BN60: =SUM(B55:BB55) -> 236 | BO60: =SUM(B60:BA60) -> 505
A61: Positivos | B61: =AJ24 -> 0 | C61: =AK24 -> 0 | D61: =AL24 -> 0 | E61: =AM24 -> 1 | F61: =AN24 -> 0 | G61: =AO24 -> 1 | H61: =AP24 -> 0 | I61: =AQ24 -> 0 | ... S61: =BA24 -> 0 | T61: =B29 -> 0 | U61: =C29 -> 0 | V61: =D29 -> 0 | W61: =E29 -> 0 | X61: =F29 -> 0 | Y61: =G29 -> 0 | Z61: =H29 -> 0 | AA61: =I29 -> 4 | ... BA61: =AI29 -> 0 | BN61: =SUM(B56:BB56) -> 26 | BO61: =SUM(B61:BA61) -> 98
...

Sheet Datos 2021-2022
B2: Dengue
B3: Municipio | C3: Sospechosos | D3: Positivos
B4: Monteagudo | C4: 18 | D4: 1
B5: Sucre | C5: 10 | D5: 1
B6: Machareti | C6: 3 | D6: 0
B7: Villa Vacaguzman | C7: 3 | D7: 0
B8: Huacareta | C8: 4 | D8: 0
B9: Padilla | C9: 2 | D9: 0
B10: Villa Serrano | C10: 1 | D10: 0
B11: Total general | C11: =SUM(C4:C10) -> 41 | D11: =SUM(D4:D10) -> 2
B16: chik
B17: Municipio | C17: Sospechosos | D17: Positivos
B18: Villa Vacaguzman | C18: 3 | D18: 0
B19: Huacareta | C19: 1 | D19: 0
B20: Monteagudo | C20: 2 | D20: 0
B21: Machareti | C21: 1 | D21: 0
B22: Total general | C22: =SUM(C18:C21) -> 7 | D22: =SUM(D18:D21) -> 0
B26: Zika
B27: Municipio | C27: Sospechosos | D27: Positivos
B28: Villa Vacaguzman | C28: 3 | D28: 0
B29: Sucre | C29: 2 | D29: 0
B30: Total general | C30: =SUM(C28:C29) -> 5 | D30: =SUM(D28:D29) -> 0
B34: Microcefalia
B35: Municipio | C35: Sospechosos | D35: Positivos
B36: Sucre | C36: 1 | D36: 0
B37: Total general | C37: =SUM(C36:C36) -> 1 | D37: =SUM(D36:D36) -> 0
C40: Sexo
B41: Edad | C41: Femenino | D41: Masculino | E41: Total general
B42: 1-4 | C42: 1 | D42: 0 | E42: =C42+D42 -> 1
B43: 5-14 | C43: 0 | D43: 0 | E43: =C43+D43 -> 0
B44: 15-59 | C44: 0 | D44: 0 | E44: =C44+D44 -> 0
B45: 60+ | C45: 0 | D45: 1 | E45: =C45+D45 -> 1
B46: Total general | C46: =SUM(C42:C45) -> 1 | D46: =SUM(D42:D45) -> 1 | E46: =C46+D46 -> 2
B49: Nexo epidemiologico
A50: Autoctonos | B50: Villa Vacaguzman | C50: 1
A51: Importados | B51: Tarija | C51: 1
B52: Total | C52: =SUM(C50:C51) -> 2
B54: Autoctonos | C54: =C52-C55 -> 1
B55: Importados | C55: =C51 -> 1
B58: Periodo epidemico | C58: Positivos | D58: % Variacion
...
